2022-12-19 15:56:38,979 INFO [GH_LOG] [고도화_GH_optimization_model_load_predict.py:337] - GH optimization model : Start
2022-12-19 15:56:45,477 INFO [GH_LOG] [고도화_GH_optimization_model_load_predict.py:302] - [38628]GH Model 실행 : 경영형-01_딸기:
2022-12-19 15:56:45,496 INFO [GH_LOG] [고도화_GH_optimization_model_load_predict.py:302] - [29324]GH Model 실행 : 교육형-01_딸기:
2022-12-19 15:56:45,513 INFO [GH_LOG] [고도화_GH_optimization_model_load_predict.py:302] - [40088]GH Model 실행 : 임대형-01_딸기:
2022-12-19 15:56:45,521 INFO [GH_LOG] [고도화_GH_optimization_model_load_predict.py:302] - [28100]GH Model 실행 : 임대형-02_딸기:
2022-12-19 15:56:45,753 ERROR [GH_LOG] [고도화_GH_optimization_model_load_predict.py:328] - Traceback (most recent call last):
  File "d:\theimz\조석준\NAVER_WORKS\스마트팜_혁신밸리\22년12월\모델고도화코드개발\스마트팜_혁신밸리_고도화_모델코드(전달)\고도화_GH_optimization_model_load_predict.py", line 306, in run
    df_in, df_out, df_con = GHModel.refine_data(self, df_in, df_out, df_con)
  File "d:\theimz\조석준\NAVER_WORKS\스마트팜_혁신밸리\22년12월\모델고도화코드개발\스마트팜_혁신밸리_고도화_모델코드(전달)\고도화_GH_optimization_model_load_predict.py", line 136, in refine_data
    df_con = df_con[['reg_date', 'sky_window', 'cg_curtain', 'flow_fan', 'hmdfc', 'crc_pump', '3way_valve_1','3way_valve_2','heat_cooler']]
  File "C:\Anaconda3\envs\tf_env\lib\site-packages\pandas\core\frame.py", line 3511, in __getitem__
    indexer = self.columns._get_indexer_strict(key, "columns")[1]
  File "C:\Anaconda3\envs\tf_env\lib\site-packages\pandas\core\indexes\base.py", line 5782, in _get_indexer_strict
    self._raise_if_missing(keyarr, indexer, axis_name)
  File "C:\Anaconda3\envs\tf_env\lib\site-packages\pandas\core\indexes\base.py", line 5845, in _raise_if_missing
    raise KeyError(f"{not_found} not in index")
KeyError: "['3way_valve_1', '3way_valve_2'] not in index"

2022-12-19 15:56:45,756 ERROR [GH_LOG] [고도화_GH_optimization_model_load_predict.py:329] - * 모듈 실행중 오류 발생 : "['3way_valve_1', '3way_valve_2'] not in index"
2022-12-19 15:56:45,756 INFO [GH_LOG] [고도화_GH_optimization_model_load_predict.py:302] - [29324]GH Model 실행 : 임대형-03_딸기:
2022-12-19 15:56:45,830 ERROR [GH_LOG] [고도화_GH_optimization_model_load_predict.py:328] - Traceback (most recent call last):
  File "d:\theimz\조석준\NAVER_WORKS\스마트팜_혁신밸리\22년12월\모델고도화코드개발\스마트팜_혁신밸리_고도화_모델코드(전달)\고도화_GH_optimization_model_load_predict.py", line 306, in run
    df_in, df_out, df_con = GHModel.refine_data(self, df_in, df_out, df_con)
  File "d:\theimz\조석준\NAVER_WORKS\스마트팜_혁신밸리\22년12월\모델고도화코드개발\스마트팜_혁신밸리_고도화_모델코드(전달)\고도화_GH_optimization_model_load_predict.py", line 136, in refine_data
    df_con = df_con[['reg_date', 'sky_window', 'cg_curtain', 'flow_fan', 'hmdfc', 'crc_pump', '3way_valve_1','3way_valve_2','heat_cooler']]
  File "C:\Anaconda3\envs\tf_env\lib\site-packages\pandas\core\frame.py", line 3511, in __getitem__
    indexer = self.columns._get_indexer_strict(key, "columns")[1]
  File "C:\Anaconda3\envs\tf_env\lib\site-packages\pandas\core\indexes\base.py", line 5782, in _get_indexer_strict
    self._raise_if_missing(keyarr, indexer, axis_name)
  File "C:\Anaconda3\envs\tf_env\lib\site-packages\pandas\core\indexes\base.py", line 5845, in _raise_if_missing
    raise KeyError(f"{not_found} not in index")
KeyError: "['3way_valve_1', '3way_valve_2'] not in index"

2022-12-19 15:56:45,833 ERROR [GH_LOG] [고도화_GH_optimization_model_load_predict.py:329] - * 모듈 실행중 오류 발생 : "['3way_valve_1', '3way_valve_2'] not in index"
2022-12-19 15:56:45,833 INFO [GH_LOG] [고도화_GH_optimization_model_load_predict.py:302] - [38628]GH Model 실행 : 임대형-04_딸기:
2022-12-19 15:56:45,869 ERROR [GH_LOG] [고도화_GH_optimization_model_load_predict.py:328] - Traceback (most recent call last):
  File "d:\theimz\조석준\NAVER_WORKS\스마트팜_혁신밸리\22년12월\모델고도화코드개발\스마트팜_혁신밸리_고도화_모델코드(전달)\고도화_GH_optimization_model_load_predict.py", line 306, in run
    df_in, df_out, df_con = GHModel.refine_data(self, df_in, df_out, df_con)
  File "d:\theimz\조석준\NAVER_WORKS\스마트팜_혁신밸리\22년12월\모델고도화코드개발\스마트팜_혁신밸리_고도화_모델코드(전달)\고도화_GH_optimization_model_load_predict.py", line 136, in refine_data
    df_con = df_con[['reg_date', 'sky_window', 'cg_curtain', 'flow_fan', 'hmdfc', 'crc_pump', '3way_valve_1','3way_valve_2','heat_cooler']]
  File "C:\Anaconda3\envs\tf_env\lib\site-packages\pandas\core\frame.py", line 3511, in __getitem__
    indexer = self.columns._get_indexer_strict(key, "columns")[1]
  File "C:\Anaconda3\envs\tf_env\lib\site-packages\pandas\core\indexes\base.py", line 5782, in _get_indexer_strict
    self._raise_if_missing(keyarr, indexer, axis_name)
  File "C:\Anaconda3\envs\tf_env\lib\site-packages\pandas\core\indexes\base.py", line 5845, in _raise_if_missing
    raise KeyError(f"{not_found} not in index")
KeyError: "['3way_valve_1', '3way_valve_2'] not in index"

2022-12-19 15:56:45,870 ERROR [GH_LOG] [고도화_GH_optimization_model_load_predict.py:329] - * 모듈 실행중 오류 발생 : "['3way_valve_1', '3way_valve_2'] not in index"
2022-12-19 15:56:45,916 ERROR [GH_LOG] [고도화_GH_optimization_model_load_predict.py:328] - Traceback (most recent call last):
  File "d:\theimz\조석준\NAVER_WORKS\스마트팜_혁신밸리\22년12월\모델고도화코드개발\스마트팜_혁신밸리_고도화_모델코드(전달)\고도화_GH_optimization_model_load_predict.py", line 306, in run
    df_in, df_out, df_con = GHModel.refine_data(self, df_in, df_out, df_con)
  File "d:\theimz\조석준\NAVER_WORKS\스마트팜_혁신밸리\22년12월\모델고도화코드개발\스마트팜_혁신밸리_고도화_모델코드(전달)\고도화_GH_optimization_model_load_predict.py", line 136, in refine_data
    df_con = df_con[['reg_date', 'sky_window', 'cg_curtain', 'flow_fan', 'hmdfc', 'crc_pump', '3way_valve_1','3way_valve_2','heat_cooler']]
  File "C:\Anaconda3\envs\tf_env\lib\site-packages\pandas\core\frame.py", line 3511, in __getitem__
    indexer = self.columns._get_indexer_strict(key, "columns")[1]
  File "C:\Anaconda3\envs\tf_env\lib\site-packages\pandas\core\indexes\base.py", line 5782, in _get_indexer_strict
    self._raise_if_missing(keyarr, indexer, axis_name)
  File "C:\Anaconda3\envs\tf_env\lib\site-packages\pandas\core\indexes\base.py", line 5845, in _raise_if_missing
    raise KeyError(f"{not_found} not in index")
KeyError: "['3way_valve_1', '3way_valve_2'] not in index"

2022-12-19 15:56:45,916 ERROR [GH_LOG] [고도화_GH_optimization_model_load_predict.py:328] - Traceback (most recent call last):
  File "d:\theimz\조석준\NAVER_WORKS\스마트팜_혁신밸리\22년12월\모델고도화코드개발\스마트팜_혁신밸리_고도화_모델코드(전달)\고도화_GH_optimization_model_load_predict.py", line 306, in run
    df_in, df_out, df_con = GHModel.refine_data(self, df_in, df_out, df_con)
  File "d:\theimz\조석준\NAVER_WORKS\스마트팜_혁신밸리\22년12월\모델고도화코드개발\스마트팜_혁신밸리_고도화_모델코드(전달)\고도화_GH_optimization_model_load_predict.py", line 136, in refine_data
    df_con = df_con[['reg_date', 'sky_window', 'cg_curtain', 'flow_fan', 'hmdfc', 'crc_pump', '3way_valve_1','3way_valve_2','heat_cooler']]
  File "C:\Anaconda3\envs\tf_env\lib\site-packages\pandas\core\frame.py", line 3511, in __getitem__
    indexer = self.columns._get_indexer_strict(key, "columns")[1]
  File "C:\Anaconda3\envs\tf_env\lib\site-packages\pandas\core\indexes\base.py", line 5782, in _get_indexer_strict
    self._raise_if_missing(keyarr, indexer, axis_name)
  File "C:\Anaconda3\envs\tf_env\lib\site-packages\pandas\core\indexes\base.py", line 5845, in _raise_if_missing
    raise KeyError(f"{not_found} not in index")
KeyError: "['3way_valve_1', '3way_valve_2'] not in index"

2022-12-19 15:56:45,918 ERROR [GH_LOG] [고도화_GH_optimization_model_load_predict.py:329] - * 모듈 실행중 오류 발생 : "['3way_valve_1', '3way_valve_2'] not in index"
2022-12-19 15:56:45,919 ERROR [GH_LOG] [고도화_GH_optimization_model_load_predict.py:329] - * 모듈 실행중 오류 발생 : "['3way_valve_1', '3way_valve_2'] not in index"
2022-12-19 15:56:45,993 ERROR [GH_LOG] [고도화_GH_optimization_model_load_predict.py:328] - Traceback (most recent call last):
  File "d:\theimz\조석준\NAVER_WORKS\스마트팜_혁신밸리\22년12월\모델고도화코드개발\스마트팜_혁신밸리_고도화_모델코드(전달)\고도화_GH_optimization_model_load_predict.py", line 306, in run
    df_in, df_out, df_con = GHModel.refine_data(self, df_in, df_out, df_con)
  File "d:\theimz\조석준\NAVER_WORKS\스마트팜_혁신밸리\22년12월\모델고도화코드개발\스마트팜_혁신밸리_고도화_모델코드(전달)\고도화_GH_optimization_model_load_predict.py", line 136, in refine_data
    df_con = df_con[['reg_date', 'sky_window', 'cg_curtain', 'flow_fan', 'hmdfc', 'crc_pump', '3way_valve_1','3way_valve_2','heat_cooler']]
  File "C:\Anaconda3\envs\tf_env\lib\site-packages\pandas\core\frame.py", line 3511, in __getitem__
    indexer = self.columns._get_indexer_strict(key, "columns")[1]
  File "C:\Anaconda3\envs\tf_env\lib\site-packages\pandas\core\indexes\base.py", line 5782, in _get_indexer_strict
    self._raise_if_missing(keyarr, indexer, axis_name)
  File "C:\Anaconda3\envs\tf_env\lib\site-packages\pandas\core\indexes\base.py", line 5845, in _raise_if_missing
    raise KeyError(f"{not_found} not in index")
KeyError: "['3way_valve_1', '3way_valve_2'] not in index"

2022-12-19 15:56:45,995 ERROR [GH_LOG] [고도화_GH_optimization_model_load_predict.py:329] - * 모듈 실행중 오류 발생 : "['3way_valve_1', '3way_valve_2'] not in index"
2022-12-19 15:56:46,594 INFO [GH_LOG] [고도화_GH_optimization_model_load_predict.py:369] - ** 모듈 실행 완료 > 총 실행시간 : 0:00:07.613375
2022-12-19 15:57:37,389 INFO [GH_LOG] [고도화_GH_optimization_model_load_predict.py:337] - GH optimization model : Start
2022-12-19 15:57:43,802 INFO [GH_LOG] [고도화_GH_optimization_model_load_predict.py:302] - [18076]GH Model 실행 : 경영형-01_딸기:
2022-12-19 15:57:43,808 INFO [GH_LOG] [고도화_GH_optimization_model_load_predict.py:302] - [45052]GH Model 실행 : 교육형-01_딸기:
2022-12-19 15:57:43,901 INFO [GH_LOG] [고도화_GH_optimization_model_load_predict.py:302] - [21624]GH Model 실행 : 임대형-01_딸기:
2022-12-19 15:57:43,916 INFO [GH_LOG] [고도화_GH_optimization_model_load_predict.py:302] - [38520]GH Model 실행 : 임대형-02_딸기:
2022-12-19 15:57:43,993 ERROR [GH_LOG] [고도화_GH_optimization_model_load_predict.py:328] - Traceback (most recent call last):
  File "d:\theimz\조석준\NAVER_WORKS\스마트팜_혁신밸리\22년12월\모델고도화코드개발\스마트팜_혁신밸리_고도화_모델코드(전달)\고도화_GH_optimization_model_load_predict.py", line 306, in run
    df_in, df_out, df_con = GHModel.refine_data(self, df_in, df_out, df_con)
  File "d:\theimz\조석준\NAVER_WORKS\스마트팜_혁신밸리\22년12월\모델고도화코드개발\스마트팜_혁신밸리_고도화_모델코드(전달)\고도화_GH_optimization_model_load_predict.py", line 136, in refine_data
    df_con = df_con[['reg_date', 'sky_window', 'cg_curtain', 'flow_fan', 'hmdfc', 'crc_pump', '3way_valve_1','3way_valve_2','heat_cooler']]
  File "C:\Anaconda3\envs\tf_env\lib\site-packages\pandas\core\frame.py", line 3511, in __getitem__
    indexer = self.columns._get_indexer_strict(key, "columns")[1]
  File "C:\Anaconda3\envs\tf_env\lib\site-packages\pandas\core\indexes\base.py", line 5782, in _get_indexer_strict
    self._raise_if_missing(keyarr, indexer, axis_name)
  File "C:\Anaconda3\envs\tf_env\lib\site-packages\pandas\core\indexes\base.py", line 5845, in _raise_if_missing
    raise KeyError(f"{not_found} not in index")
KeyError: "['3way_valve_1', '3way_valve_2'] not in index"

2022-12-19 15:57:43,993 ERROR [GH_LOG] [고도화_GH_optimization_model_load_predict.py:328] - Traceback (most recent call last):
  File "d:\theimz\조석준\NAVER_WORKS\스마트팜_혁신밸리\22년12월\모델고도화코드개발\스마트팜_혁신밸리_고도화_모델코드(전달)\고도화_GH_optimization_model_load_predict.py", line 306, in run
    df_in, df_out, df_con = GHModel.refine_data(self, df_in, df_out, df_con)
  File "d:\theimz\조석준\NAVER_WORKS\스마트팜_혁신밸리\22년12월\모델고도화코드개발\스마트팜_혁신밸리_고도화_모델코드(전달)\고도화_GH_optimization_model_load_predict.py", line 136, in refine_data
    df_con = df_con[['reg_date', 'sky_window', 'cg_curtain', 'flow_fan', 'hmdfc', 'crc_pump', '3way_valve_1','3way_valve_2','heat_cooler']]
  File "C:\Anaconda3\envs\tf_env\lib\site-packages\pandas\core\frame.py", line 3511, in __getitem__
    indexer = self.columns._get_indexer_strict(key, "columns")[1]
  File "C:\Anaconda3\envs\tf_env\lib\site-packages\pandas\core\indexes\base.py", line 5782, in _get_indexer_strict
    self._raise_if_missing(keyarr, indexer, axis_name)
  File "C:\Anaconda3\envs\tf_env\lib\site-packages\pandas\core\indexes\base.py", line 5845, in _raise_if_missing
    raise KeyError(f"{not_found} not in index")
KeyError: "['3way_valve_1', '3way_valve_2'] not in index"

2022-12-19 15:57:43,995 ERROR [GH_LOG] [고도화_GH_optimization_model_load_predict.py:329] - * 모듈 실행중 오류 발생 : "['3way_valve_1', '3way_valve_2'] not in index"
2022-12-19 15:57:43,996 ERROR [GH_LOG] [고도화_GH_optimization_model_load_predict.py:329] - * 모듈 실행중 오류 발생 : "['3way_valve_1', '3way_valve_2'] not in index"
2022-12-19 15:57:43,997 INFO [GH_LOG] [고도화_GH_optimization_model_load_predict.py:302] - [45052]GH Model 실행 : 임대형-03_딸기:
2022-12-19 15:57:43,997 INFO [GH_LOG] [고도화_GH_optimization_model_load_predict.py:302] - [18076]GH Model 실행 : 임대형-04_딸기:
2022-12-19 15:57:44,111 ERROR [GH_LOG] [고도화_GH_optimization_model_load_predict.py:328] - Traceback (most recent call last):
  File "d:\theimz\조석준\NAVER_WORKS\스마트팜_혁신밸리\22년12월\모델고도화코드개발\스마트팜_혁신밸리_고도화_모델코드(전달)\고도화_GH_optimization_model_load_predict.py", line 306, in run
    df_in, df_out, df_con = GHModel.refine_data(self, df_in, df_out, df_con)
  File "d:\theimz\조석준\NAVER_WORKS\스마트팜_혁신밸리\22년12월\모델고도화코드개발\스마트팜_혁신밸리_고도화_모델코드(전달)\고도화_GH_optimization_model_load_predict.py", line 136, in refine_data
    df_con = df_con[['reg_date', 'sky_window', 'cg_curtain', 'flow_fan', 'hmdfc', 'crc_pump', '3way_valve_1','3way_valve_2','heat_cooler']]
  File "C:\Anaconda3\envs\tf_env\lib\site-packages\pandas\core\frame.py", line 3511, in __getitem__
    indexer = self.columns._get_indexer_strict(key, "columns")[1]
  File "C:\Anaconda3\envs\tf_env\lib\site-packages\pandas\core\indexes\base.py", line 5782, in _get_indexer_strict
    self._raise_if_missing(keyarr, indexer, axis_name)
  File "C:\Anaconda3\envs\tf_env\lib\site-packages\pandas\core\indexes\base.py", line 5845, in _raise_if_missing
    raise KeyError(f"{not_found} not in index")
KeyError: "['3way_valve_1', '3way_valve_2'] not in index"

2022-12-19 15:57:44,113 ERROR [GH_LOG] [고도화_GH_optimization_model_load_predict.py:329] - * 모듈 실행중 오류 발생 : "['3way_valve_1', '3way_valve_2'] not in index"
2022-12-19 15:57:44,123 ERROR [GH_LOG] [고도화_GH_optimization_model_load_predict.py:328] - Traceback (most recent call last):
  File "d:\theimz\조석준\NAVER_WORKS\스마트팜_혁신밸리\22년12월\모델고도화코드개발\스마트팜_혁신밸리_고도화_모델코드(전달)\고도화_GH_optimization_model_load_predict.py", line 306, in run
    df_in, df_out, df_con = GHModel.refine_data(self, df_in, df_out, df_con)
  File "d:\theimz\조석준\NAVER_WORKS\스마트팜_혁신밸리\22년12월\모델고도화코드개발\스마트팜_혁신밸리_고도화_모델코드(전달)\고도화_GH_optimization_model_load_predict.py", line 136, in refine_data
    df_con = df_con[['reg_date', 'sky_window', 'cg_curtain', 'flow_fan', 'hmdfc', 'crc_pump', '3way_valve_1','3way_valve_2','heat_cooler']]
  File "C:\Anaconda3\envs\tf_env\lib\site-packages\pandas\core\frame.py", line 3511, in __getitem__
    indexer = self.columns._get_indexer_strict(key, "columns")[1]
  File "C:\Anaconda3\envs\tf_env\lib\site-packages\pandas\core\indexes\base.py", line 5782, in _get_indexer_strict
    self._raise_if_missing(keyarr, indexer, axis_name)
  File "C:\Anaconda3\envs\tf_env\lib\site-packages\pandas\core\indexes\base.py", line 5845, in _raise_if_missing
    raise KeyError(f"{not_found} not in index")
KeyError: "['3way_valve_1', '3way_valve_2'] not in index"

2022-12-19 15:57:44,125 ERROR [GH_LOG] [고도화_GH_optimization_model_load_predict.py:329] - * 모듈 실행중 오류 발생 : "['3way_valve_1', '3way_valve_2'] not in index"
2022-12-19 15:57:44,149 ERROR [GH_LOG] [고도화_GH_optimization_model_load_predict.py:328] - Traceback (most recent call last):
  File "d:\theimz\조석준\NAVER_WORKS\스마트팜_혁신밸리\22년12월\모델고도화코드개발\스마트팜_혁신밸리_고도화_모델코드(전달)\고도화_GH_optimization_model_load_predict.py", line 306, in run
    df_in, df_out, df_con = GHModel.refine_data(self, df_in, df_out, df_con)
  File "d:\theimz\조석준\NAVER_WORKS\스마트팜_혁신밸리\22년12월\모델고도화코드개발\스마트팜_혁신밸리_고도화_모델코드(전달)\고도화_GH_optimization_model_load_predict.py", line 136, in refine_data
    df_con = df_con[['reg_date', 'sky_window', 'cg_curtain', 'flow_fan', 'hmdfc', 'crc_pump', '3way_valve_1','3way_valve_2','heat_cooler']]
  File "C:\Anaconda3\envs\tf_env\lib\site-packages\pandas\core\frame.py", line 3511, in __getitem__
    indexer = self.columns._get_indexer_strict(key, "columns")[1]
  File "C:\Anaconda3\envs\tf_env\lib\site-packages\pandas\core\indexes\base.py", line 5782, in _get_indexer_strict
    self._raise_if_missing(keyarr, indexer, axis_name)
  File "C:\Anaconda3\envs\tf_env\lib\site-packages\pandas\core\indexes\base.py", line 5845, in _raise_if_missing
    raise KeyError(f"{not_found} not in index")
KeyError: "['3way_valve_1', '3way_valve_2'] not in index"

2022-12-19 15:57:44,151 ERROR [GH_LOG] [고도화_GH_optimization_model_load_predict.py:329] - * 모듈 실행중 오류 발생 : "['3way_valve_1', '3way_valve_2'] not in index"
2022-12-19 15:57:44,570 ERROR [GH_LOG] [고도화_GH_optimization_model_load_predict.py:328] - Traceback (most recent call last):
  File "d:\theimz\조석준\NAVER_WORKS\스마트팜_혁신밸리\22년12월\모델고도화코드개발\스마트팜_혁신밸리_고도화_모델코드(전달)\고도화_GH_optimization_model_load_predict.py", line 306, in run
    df_in, df_out, df_con = GHModel.refine_data(self, df_in, df_out, df_con)
  File "d:\theimz\조석준\NAVER_WORKS\스마트팜_혁신밸리\22년12월\모델고도화코드개발\스마트팜_혁신밸리_고도화_모델코드(전달)\고도화_GH_optimization_model_load_predict.py", line 136, in refine_data
    df_con = df_con[['reg_date', 'sky_window', 'cg_curtain', 'flow_fan', 'hmdfc', 'crc_pump', '3way_valve_1','3way_valve_2','heat_cooler']]
  File "C:\Anaconda3\envs\tf_env\lib\site-packages\pandas\core\frame.py", line 3511, in __getitem__
    indexer = self.columns._get_indexer_strict(key, "columns")[1]
  File "C:\Anaconda3\envs\tf_env\lib\site-packages\pandas\core\indexes\base.py", line 5782, in _get_indexer_strict
    self._raise_if_missing(keyarr, indexer, axis_name)
  File "C:\Anaconda3\envs\tf_env\lib\site-packages\pandas\core\indexes\base.py", line 5845, in _raise_if_missing
    raise KeyError(f"{not_found} not in index")
KeyError: "['3way_valve_1', '3way_valve_2'] not in index"

2022-12-19 15:57:44,571 ERROR [GH_LOG] [고도화_GH_optimization_model_load_predict.py:329] - * 모듈 실행중 오류 발생 : "['3way_valve_1', '3way_valve_2'] not in index"
2022-12-19 15:57:45,164 INFO [GH_LOG] [고도화_GH_optimization_model_load_predict.py:369] - ** 모듈 실행 완료 > 총 실행시간 : 0:00:07.774834
2022-12-19 16:00:13,487 INFO [GH_LOG] [고도화_GH_optimization_model_load_predict.py:337] - GH optimization model : Start
2022-12-19 16:00:19,651 INFO [GH_LOG] [고도화_GH_optimization_model_load_predict.py:302] - [22684]GH Model 실행 : 경영형-01_딸기:
2022-12-19 16:00:19,763 INFO [GH_LOG] [고도화_GH_optimization_model_load_predict.py:302] - [28536]GH Model 실행 : 교육형-01_딸기:
2022-12-19 16:00:19,767 INFO [GH_LOG] [고도화_GH_optimization_model_load_predict.py:302] - [36444]GH Model 실행 : 임대형-01_딸기:
2022-12-19 16:00:19,771 INFO [GH_LOG] [고도화_GH_optimization_model_load_predict.py:302] - [37216]GH Model 실행 : 임대형-02_딸기:
2022-12-19 16:00:19,842 ERROR [GH_LOG] [고도화_GH_optimization_model_load_predict.py:328] - Traceback (most recent call last):
  File "d:\theimz\조석준\NAVER_WORKS\스마트팜_혁신밸리\22년12월\모델고도화코드개발\스마트팜_혁신밸리_고도화_모델코드(전달)\고도화_GH_optimization_model_load_predict.py", line 306, in run
    df_in, df_out, df_con = GHModel.refine_data(self, df_in, df_out, df_con)
  File "d:\theimz\조석준\NAVER_WORKS\스마트팜_혁신밸리\22년12월\모델고도화코드개발\스마트팜_혁신밸리_고도화_모델코드(전달)\고도화_GH_optimization_model_load_predict.py", line 136, in refine_data
    df_con = df_con[['reg_date', 'sky_window', 'cg_curtain', 'flow_fan', 'hmdfc', 'crc_pump', '3way_valve_1','3way_valve_2','heat_cooler']]
  File "C:\Anaconda3\envs\tf_env\lib\site-packages\pandas\core\frame.py", line 3511, in __getitem__
    indexer = self.columns._get_indexer_strict(key, "columns")[1]
  File "C:\Anaconda3\envs\tf_env\lib\site-packages\pandas\core\indexes\base.py", line 5782, in _get_indexer_strict
    self._raise_if_missing(keyarr, indexer, axis_name)
  File "C:\Anaconda3\envs\tf_env\lib\site-packages\pandas\core\indexes\base.py", line 5845, in _raise_if_missing
    raise KeyError(f"{not_found} not in index")
KeyError: "['3way_valve_1', '3way_valve_2'] not in index"

2022-12-19 16:00:19,844 ERROR [GH_LOG] [고도화_GH_optimization_model_load_predict.py:329] - * 모듈 실행중 오류 발생 : "['3way_valve_1', '3way_valve_2'] not in index"
2022-12-19 16:00:19,845 INFO [GH_LOG] [고도화_GH_optimization_model_load_predict.py:302] - [22684]GH Model 실행 : 임대형-03_딸기:
2022-12-19 16:00:19,926 ERROR [GH_LOG] [고도화_GH_optimization_model_load_predict.py:328] - Traceback (most recent call last):
  File "d:\theimz\조석준\NAVER_WORKS\스마트팜_혁신밸리\22년12월\모델고도화코드개발\스마트팜_혁신밸리_고도화_모델코드(전달)\고도화_GH_optimization_model_load_predict.py", line 306, in run
    df_in, df_out, df_con = GHModel.refine_data(self, df_in, df_out, df_con)
  File "d:\theimz\조석준\NAVER_WORKS\스마트팜_혁신밸리\22년12월\모델고도화코드개발\스마트팜_혁신밸리_고도화_모델코드(전달)\고도화_GH_optimization_model_load_predict.py", line 136, in refine_data
    df_con = df_con[['reg_date', 'sky_window', 'cg_curtain', 'flow_fan', 'hmdfc', 'crc_pump', '3way_valve_1','3way_valve_2','heat_cooler']]
  File "C:\Anaconda3\envs\tf_env\lib\site-packages\pandas\core\frame.py", line 3511, in __getitem__
    indexer = self.columns._get_indexer_strict(key, "columns")[1]
  File "C:\Anaconda3\envs\tf_env\lib\site-packages\pandas\core\indexes\base.py", line 5782, in _get_indexer_strict
    self._raise_if_missing(keyarr, indexer, axis_name)
  File "C:\Anaconda3\envs\tf_env\lib\site-packages\pandas\core\indexes\base.py", line 5845, in _raise_if_missing
    raise KeyError(f"{not_found} not in index")
KeyError: "['3way_valve_1', '3way_valve_2'] not in index"

2022-12-19 16:00:19,927 ERROR [GH_LOG] [고도화_GH_optimization_model_load_predict.py:329] - * 모듈 실행중 오류 발생 : "['3way_valve_1', '3way_valve_2'] not in index"
2022-12-19 16:00:19,928 INFO [GH_LOG] [고도화_GH_optimization_model_load_predict.py:302] - [28536]GH Model 실행 : 임대형-04_딸기:
2022-12-19 16:00:19,953 ERROR [GH_LOG] [고도화_GH_optimization_model_load_predict.py:328] - Traceback (most recent call last):
  File "d:\theimz\조석준\NAVER_WORKS\스마트팜_혁신밸리\22년12월\모델고도화코드개발\스마트팜_혁신밸리_고도화_모델코드(전달)\고도화_GH_optimization_model_load_predict.py", line 306, in run
    df_in, df_out, df_con = GHModel.refine_data(self, df_in, df_out, df_con)
  File "d:\theimz\조석준\NAVER_WORKS\스마트팜_혁신밸리\22년12월\모델고도화코드개발\스마트팜_혁신밸리_고도화_모델코드(전달)\고도화_GH_optimization_model_load_predict.py", line 136, in refine_data
    df_con = df_con[['reg_date', 'sky_window', 'cg_curtain', 'flow_fan', 'hmdfc', 'crc_pump', '3way_valve_1','3way_valve_2','heat_cooler']]
  File "C:\Anaconda3\envs\tf_env\lib\site-packages\pandas\core\frame.py", line 3511, in __getitem__
    indexer = self.columns._get_indexer_strict(key, "columns")[1]
  File "C:\Anaconda3\envs\tf_env\lib\site-packages\pandas\core\indexes\base.py", line 5782, in _get_indexer_strict
    self._raise_if_missing(keyarr, indexer, axis_name)
  File "C:\Anaconda3\envs\tf_env\lib\site-packages\pandas\core\indexes\base.py", line 5845, in _raise_if_missing
    raise KeyError(f"{not_found} not in index")
KeyError: "['3way_valve_1', '3way_valve_2'] not in index"

2022-12-19 16:00:19,953 ERROR [GH_LOG] [고도화_GH_optimization_model_load_predict.py:328] - Traceback (most recent call last):
  File "d:\theimz\조석준\NAVER_WORKS\스마트팜_혁신밸리\22년12월\모델고도화코드개발\스마트팜_혁신밸리_고도화_모델코드(전달)\고도화_GH_optimization_model_load_predict.py", line 306, in run
    df_in, df_out, df_con = GHModel.refine_data(self, df_in, df_out, df_con)
  File "d:\theimz\조석준\NAVER_WORKS\스마트팜_혁신밸리\22년12월\모델고도화코드개발\스마트팜_혁신밸리_고도화_모델코드(전달)\고도화_GH_optimization_model_load_predict.py", line 136, in refine_data
    df_con = df_con[['reg_date', 'sky_window', 'cg_curtain', 'flow_fan', 'hmdfc', 'crc_pump', '3way_valve_1','3way_valve_2','heat_cooler']]
  File "C:\Anaconda3\envs\tf_env\lib\site-packages\pandas\core\frame.py", line 3511, in __getitem__
    indexer = self.columns._get_indexer_strict(key, "columns")[1]
  File "C:\Anaconda3\envs\tf_env\lib\site-packages\pandas\core\indexes\base.py", line 5782, in _get_indexer_strict
    self._raise_if_missing(keyarr, indexer, axis_name)
  File "C:\Anaconda3\envs\tf_env\lib\site-packages\pandas\core\indexes\base.py", line 5845, in _raise_if_missing
    raise KeyError(f"{not_found} not in index")
KeyError: "['3way_valve_1', '3way_valve_2'] not in index"

2022-12-19 16:00:19,955 ERROR [GH_LOG] [고도화_GH_optimization_model_load_predict.py:329] - * 모듈 실행중 오류 발생 : "['3way_valve_1', '3way_valve_2'] not in index"
2022-12-19 16:00:19,956 ERROR [GH_LOG] [고도화_GH_optimization_model_load_predict.py:329] - * 모듈 실행중 오류 발생 : "['3way_valve_1', '3way_valve_2'] not in index"
2022-12-19 16:00:20,004 ERROR [GH_LOG] [고도화_GH_optimization_model_load_predict.py:328] - Traceback (most recent call last):
  File "d:\theimz\조석준\NAVER_WORKS\스마트팜_혁신밸리\22년12월\모델고도화코드개발\스마트팜_혁신밸리_고도화_모델코드(전달)\고도화_GH_optimization_model_load_predict.py", line 306, in run
    df_in, df_out, df_con = GHModel.refine_data(self, df_in, df_out, df_con)
  File "d:\theimz\조석준\NAVER_WORKS\스마트팜_혁신밸리\22년12월\모델고도화코드개발\스마트팜_혁신밸리_고도화_모델코드(전달)\고도화_GH_optimization_model_load_predict.py", line 136, in refine_data
    df_con = df_con[['reg_date', 'sky_window', 'cg_curtain', 'flow_fan', 'hmdfc', 'crc_pump', '3way_valve_1','3way_valve_2','heat_cooler']]
  File "C:\Anaconda3\envs\tf_env\lib\site-packages\pandas\core\frame.py", line 3511, in __getitem__
    indexer = self.columns._get_indexer_strict(key, "columns")[1]
  File "C:\Anaconda3\envs\tf_env\lib\site-packages\pandas\core\indexes\base.py", line 5782, in _get_indexer_strict
    self._raise_if_missing(keyarr, indexer, axis_name)
  File "C:\Anaconda3\envs\tf_env\lib\site-packages\pandas\core\indexes\base.py", line 5845, in _raise_if_missing
    raise KeyError(f"{not_found} not in index")
KeyError: "['3way_valve_1', '3way_valve_2'] not in index"

2022-12-19 16:00:20,006 ERROR [GH_LOG] [고도화_GH_optimization_model_load_predict.py:329] - * 모듈 실행중 오류 발생 : "['3way_valve_1', '3way_valve_2'] not in index"
2022-12-19 16:00:20,093 ERROR [GH_LOG] [고도화_GH_optimization_model_load_predict.py:328] - Traceback (most recent call last):
  File "d:\theimz\조석준\NAVER_WORKS\스마트팜_혁신밸리\22년12월\모델고도화코드개발\스마트팜_혁신밸리_고도화_모델코드(전달)\고도화_GH_optimization_model_load_predict.py", line 306, in run
    df_in, df_out, df_con = GHModel.refine_data(self, df_in, df_out, df_con)
  File "d:\theimz\조석준\NAVER_WORKS\스마트팜_혁신밸리\22년12월\모델고도화코드개발\스마트팜_혁신밸리_고도화_모델코드(전달)\고도화_GH_optimization_model_load_predict.py", line 136, in refine_data
    df_con = df_con[['reg_date', 'sky_window', 'cg_curtain', 'flow_fan', 'hmdfc', 'crc_pump', '3way_valve_1','3way_valve_2','heat_cooler']]
  File "C:\Anaconda3\envs\tf_env\lib\site-packages\pandas\core\frame.py", line 3511, in __getitem__
    indexer = self.columns._get_indexer_strict(key, "columns")[1]
  File "C:\Anaconda3\envs\tf_env\lib\site-packages\pandas\core\indexes\base.py", line 5782, in _get_indexer_strict
    self._raise_if_missing(keyarr, indexer, axis_name)
  File "C:\Anaconda3\envs\tf_env\lib\site-packages\pandas\core\indexes\base.py", line 5845, in _raise_if_missing
    raise KeyError(f"{not_found} not in index")
KeyError: "['3way_valve_1', '3way_valve_2'] not in index"

2022-12-19 16:00:20,095 ERROR [GH_LOG] [고도화_GH_optimization_model_load_predict.py:329] - * 모듈 실행중 오류 발생 : "['3way_valve_1', '3way_valve_2'] not in index"
2022-12-19 16:00:20,672 INFO [GH_LOG] [고도화_GH_optimization_model_load_predict.py:369] - ** 모듈 실행 완료 > 총 실행시간 : 0:00:07.184404
2022-12-19 16:01:30,912 INFO [GH_LOG] [고도화_GH_optimization_model_load_predict.py:337] - GH optimization model : Start
2022-12-19 16:01:37,084 INFO [GH_LOG] [고도화_GH_optimization_model_load_predict.py:302] - [10816]GH Model 실행 : 경영형-01_딸기:
2022-12-19 16:01:37,086 INFO [GH_LOG] [고도화_GH_optimization_model_load_predict.py:302] - [26472]GH Model 실행 : 교육형-01_딸기:
2022-12-19 16:01:37,179 INFO [GH_LOG] [고도화_GH_optimization_model_load_predict.py:302] - [35352]GH Model 실행 : 임대형-01_딸기:
2022-12-19 16:01:37,179 INFO [GH_LOG] [고도화_GH_optimization_model_load_predict.py:302] - [34840]GH Model 실행 : 임대형-02_딸기:
2022-12-19 16:01:37,437 ERROR [GH_LOG] [고도화_GH_optimization_model_load_predict.py:328] - Traceback (most recent call last):
  File "d:\theimz\조석준\NAVER_WORKS\스마트팜_혁신밸리\22년12월\모델고도화코드개발\스마트팜_혁신밸리_고도화_모델코드(전달)\고도화_GH_optimization_model_load_predict.py", line 308, in run
    df_in = GHModel.preprocess_in(self, df_in)
  File "d:\theimz\조석준\NAVER_WORKS\스마트팜_혁신밸리\22년12월\모델고도화코드개발\스마트팜_혁신밸리_고도화_모델코드(전달)\고도화_GH_optimization_model_load_predict.py", line 147, in preprocess_in
    df_in['reg_date'].iloc[i] = datetime(temp.year, temp.month, temp.day, temp.hour, (temp.minute - temp.minute % 10))
  File "C:\Anaconda3\envs\tf_env\lib\site-packages\pandas\core\indexing.py", line 713, in __setitem__
    self._has_valid_setitem_indexer(key)
  File "C:\Anaconda3\envs\tf_env\lib\site-packages\pandas\core\indexing.py", line 1413, in _has_valid_setitem_indexer
    raise IndexError("iloc cannot enlarge its target object")
IndexError: iloc cannot enlarge its target object

2022-12-19 16:01:37,437 ERROR [GH_LOG] [고도화_GH_optimization_model_load_predict.py:328] - Traceback (most recent call last):
  File "d:\theimz\조석준\NAVER_WORKS\스마트팜_혁신밸리\22년12월\모델고도화코드개발\스마트팜_혁신밸리_고도화_모델코드(전달)\고도화_GH_optimization_model_load_predict.py", line 308, in run
    df_in = GHModel.preprocess_in(self, df_in)
  File "d:\theimz\조석준\NAVER_WORKS\스마트팜_혁신밸리\22년12월\모델고도화코드개발\스마트팜_혁신밸리_고도화_모델코드(전달)\고도화_GH_optimization_model_load_predict.py", line 147, in preprocess_in
    df_in['reg_date'].iloc[i] = datetime(temp.year, temp.month, temp.day, temp.hour, (temp.minute - temp.minute % 10))
  File "C:\Anaconda3\envs\tf_env\lib\site-packages\pandas\core\indexing.py", line 713, in __setitem__
    self._has_valid_setitem_indexer(key)
  File "C:\Anaconda3\envs\tf_env\lib\site-packages\pandas\core\indexing.py", line 1413, in _has_valid_setitem_indexer
    raise IndexError("iloc cannot enlarge its target object")
IndexError: iloc cannot enlarge its target object

2022-12-19 16:01:37,439 ERROR [GH_LOG] [고도화_GH_optimization_model_load_predict.py:329] - * 모듈 실행중 오류 발생 : iloc cannot enlarge its target object
2022-12-19 16:01:37,440 ERROR [GH_LOG] [고도화_GH_optimization_model_load_predict.py:329] - * 모듈 실행중 오류 발생 : iloc cannot enlarge its target object
2022-12-19 16:01:37,440 INFO [GH_LOG] [고도화_GH_optimization_model_load_predict.py:302] - [34840]GH Model 실행 : 임대형-03_딸기:
2022-12-19 16:01:37,441 INFO [GH_LOG] [고도화_GH_optimization_model_load_predict.py:302] - [35352]GH Model 실행 : 임대형-04_딸기:
2022-12-19 16:01:37,624 ERROR [GH_LOG] [고도화_GH_optimization_model_load_predict.py:328] - Traceback (most recent call last):
  File "d:\theimz\조석준\NAVER_WORKS\스마트팜_혁신밸리\22년12월\모델고도화코드개발\스마트팜_혁신밸리_고도화_모델코드(전달)\고도화_GH_optimization_model_load_predict.py", line 308, in run
    df_in = GHModel.preprocess_in(self, df_in)
  File "d:\theimz\조석준\NAVER_WORKS\스마트팜_혁신밸리\22년12월\모델고도화코드개발\스마트팜_혁신밸리_고도화_모델코드(전달)\고도화_GH_optimization_model_load_predict.py", line 147, in preprocess_in
    df_in['reg_date'].iloc[i] = datetime(temp.year, temp.month, temp.day, temp.hour, (temp.minute - temp.minute % 10))
  File "C:\Anaconda3\envs\tf_env\lib\site-packages\pandas\core\indexing.py", line 713, in __setitem__
    self._has_valid_setitem_indexer(key)
  File "C:\Anaconda3\envs\tf_env\lib\site-packages\pandas\core\indexing.py", line 1413, in _has_valid_setitem_indexer
    raise IndexError("iloc cannot enlarge its target object")
IndexError: iloc cannot enlarge its target object

2022-12-19 16:01:37,626 ERROR [GH_LOG] [고도화_GH_optimization_model_load_predict.py:329] - * 모듈 실행중 오류 발생 : iloc cannot enlarge its target object
2022-12-19 16:01:37,793 ERROR [GH_LOG] [고도화_GH_optimization_model_load_predict.py:328] - Traceback (most recent call last):
  File "d:\theimz\조석준\NAVER_WORKS\스마트팜_혁신밸리\22년12월\모델고도화코드개발\스마트팜_혁신밸리_고도화_모델코드(전달)\고도화_GH_optimization_model_load_predict.py", line 308, in run
    df_in = GHModel.preprocess_in(self, df_in)
  File "d:\theimz\조석준\NAVER_WORKS\스마트팜_혁신밸리\22년12월\모델고도화코드개발\스마트팜_혁신밸리_고도화_모델코드(전달)\고도화_GH_optimization_model_load_predict.py", line 147, in preprocess_in
    df_in['reg_date'].iloc[i] = datetime(temp.year, temp.month, temp.day, temp.hour, (temp.minute - temp.minute % 10))
  File "C:\Anaconda3\envs\tf_env\lib\site-packages\pandas\core\indexing.py", line 713, in __setitem__
    self._has_valid_setitem_indexer(key)
  File "C:\Anaconda3\envs\tf_env\lib\site-packages\pandas\core\indexing.py", line 1413, in _has_valid_setitem_indexer
    raise IndexError("iloc cannot enlarge its target object")
IndexError: iloc cannot enlarge its target object

2022-12-19 16:01:37,794 ERROR [GH_LOG] [고도화_GH_optimization_model_load_predict.py:329] - * 모듈 실행중 오류 발생 : iloc cannot enlarge its target object
2022-12-19 16:01:42,420 ERROR [GH_LOG] [고도화_GH_optimization_model_load_predict.py:328] - Traceback (most recent call last):
  File "d:\theimz\조석준\NAVER_WORKS\스마트팜_혁신밸리\22년12월\모델고도화코드개발\스마트팜_혁신밸리_고도화_모델코드(전달)\고도화_GH_optimization_model_load_predict.py", line 317, in run
    df = GHModel.process_missing_val(self, df)
  File "d:\theimz\조석준\NAVER_WORKS\스마트팜_혁신밸리\22년12월\모델고도화코드개발\스마트팜_혁신밸리_고도화_모델코드(전달)\고도화_GH_optimization_model_load_predict.py", line 201, in process_missing_val
    df = df[['new_date', 'fclty_nm', 'crop_nm', 'tp_x', 'hd_x', 'co2',
  File "C:\Anaconda3\envs\tf_env\lib\site-packages\pandas\core\frame.py", line 3511, in __getitem__
    indexer = self.columns._get_indexer_strict(key, "columns")[1]
  File "C:\Anaconda3\envs\tf_env\lib\site-packages\pandas\core\indexes\base.py", line 5782, in _get_indexer_strict
    self._raise_if_missing(keyarr, indexer, axis_name)
  File "C:\Anaconda3\envs\tf_env\lib\site-packages\pandas\core\indexes\base.py", line 5845, in _raise_if_missing
    raise KeyError(f"{not_found} not in index")
KeyError: "['hd_x'] not in index"

2022-12-19 16:01:42,422 ERROR [GH_LOG] [고도화_GH_optimization_model_load_predict.py:329] - * 모듈 실행중 오류 발생 : "['hd_x'] not in index"
2022-12-19 16:01:42,425 ERROR [GH_LOG] [고도화_GH_optimization_model_load_predict.py:328] - Traceback (most recent call last):
  File "d:\theimz\조석준\NAVER_WORKS\스마트팜_혁신밸리\22년12월\모델고도화코드개발\스마트팜_혁신밸리_고도화_모델코드(전달)\고도화_GH_optimization_model_load_predict.py", line 317, in run
    df = GHModel.process_missing_val(self, df)
  File "d:\theimz\조석준\NAVER_WORKS\스마트팜_혁신밸리\22년12월\모델고도화코드개발\스마트팜_혁신밸리_고도화_모델코드(전달)\고도화_GH_optimization_model_load_predict.py", line 201, in process_missing_val
    df = df[['new_date', 'fclty_nm', 'crop_nm', 'tp_x', 'hd_x', 'co2',
  File "C:\Anaconda3\envs\tf_env\lib\site-packages\pandas\core\frame.py", line 3511, in __getitem__
    indexer = self.columns._get_indexer_strict(key, "columns")[1]
  File "C:\Anaconda3\envs\tf_env\lib\site-packages\pandas\core\indexes\base.py", line 5782, in _get_indexer_strict
    self._raise_if_missing(keyarr, indexer, axis_name)
  File "C:\Anaconda3\envs\tf_env\lib\site-packages\pandas\core\indexes\base.py", line 5845, in _raise_if_missing
    raise KeyError(f"{not_found} not in index")
KeyError: "['hd_x'] not in index"

2022-12-19 16:01:42,427 ERROR [GH_LOG] [고도화_GH_optimization_model_load_predict.py:329] - * 모듈 실행중 오류 발생 : "['hd_x'] not in index"
2022-12-19 16:01:43,001 INFO [GH_LOG] [고도화_GH_optimization_model_load_predict.py:369] - ** 모듈 실행 완료 > 총 실행시간 : 0:00:12.089041
2022-12-19 16:02:43,077 INFO [GH_LOG] [고도화_GH_optimization_model_load_predict.py:337] - GH optimization model : Start
2022-12-19 16:02:49,561 INFO [GH_LOG] [고도화_GH_optimization_model_load_predict.py:302] - [35280]GH Model 실행 : 경영형-01_딸기:
2022-12-19 16:02:49,653 INFO [GH_LOG] [고도화_GH_optimization_model_load_predict.py:302] - [13136]GH Model 실행 : 교육형-01_딸기:
2022-12-19 16:02:49,668 INFO [GH_LOG] [고도화_GH_optimization_model_load_predict.py:302] - [13864]GH Model 실행 : 임대형-01_딸기:
2022-12-19 16:02:49,670 INFO [GH_LOG] [고도화_GH_optimization_model_load_predict.py:302] - [38080]GH Model 실행 : 임대형-02_딸기:
2022-12-19 16:02:49,856 ERROR [GH_LOG] [고도화_GH_optimization_model_load_predict.py:328] - Traceback (most recent call last):
  File "d:\theimz\조석준\NAVER_WORKS\스마트팜_혁신밸리\22년12월\모델고도화코드개발\스마트팜_혁신밸리_고도화_모델코드(전달)\고도화_GH_optimization_model_load_predict.py", line 308, in run
    df_in = GHModel.preprocess_in(self, df_in)
  File "d:\theimz\조석준\NAVER_WORKS\스마트팜_혁신밸리\22년12월\모델고도화코드개발\스마트팜_혁신밸리_고도화_모델코드(전달)\고도화_GH_optimization_model_load_predict.py", line 147, in preprocess_in
    df_in['reg_date'].iloc[i] = datetime(temp.year, temp.month, temp.day, temp.hour, (temp.minute - temp.minute % 10))
  File "C:\Anaconda3\envs\tf_env\lib\site-packages\pandas\core\indexing.py", line 713, in __setitem__
    self._has_valid_setitem_indexer(key)
  File "C:\Anaconda3\envs\tf_env\lib\site-packages\pandas\core\indexing.py", line 1413, in _has_valid_setitem_indexer
    raise IndexError("iloc cannot enlarge its target object")
IndexError: iloc cannot enlarge its target object

2022-12-19 16:02:49,856 ERROR [GH_LOG] [고도화_GH_optimization_model_load_predict.py:328] - Traceback (most recent call last):
  File "d:\theimz\조석준\NAVER_WORKS\스마트팜_혁신밸리\22년12월\모델고도화코드개발\스마트팜_혁신밸리_고도화_모델코드(전달)\고도화_GH_optimization_model_load_predict.py", line 308, in run
    df_in = GHModel.preprocess_in(self, df_in)
  File "d:\theimz\조석준\NAVER_WORKS\스마트팜_혁신밸리\22년12월\모델고도화코드개발\스마트팜_혁신밸리_고도화_모델코드(전달)\고도화_GH_optimization_model_load_predict.py", line 147, in preprocess_in
    df_in['reg_date'].iloc[i] = datetime(temp.year, temp.month, temp.day, temp.hour, (temp.minute - temp.minute % 10))
  File "C:\Anaconda3\envs\tf_env\lib\site-packages\pandas\core\indexing.py", line 713, in __setitem__
    self._has_valid_setitem_indexer(key)
  File "C:\Anaconda3\envs\tf_env\lib\site-packages\pandas\core\indexing.py", line 1413, in _has_valid_setitem_indexer
    raise IndexError("iloc cannot enlarge its target object")
IndexError: iloc cannot enlarge its target object

2022-12-19 16:02:49,858 ERROR [GH_LOG] [고도화_GH_optimization_model_load_predict.py:329] - * 모듈 실행중 오류 발생 : iloc cannot enlarge its target object
2022-12-19 16:02:49,859 ERROR [GH_LOG] [고도화_GH_optimization_model_load_predict.py:329] - * 모듈 실행중 오류 발생 : iloc cannot enlarge its target object
2022-12-19 16:02:49,860 INFO [GH_LOG] [고도화_GH_optimization_model_load_predict.py:302] - [38080]GH Model 실행 : 임대형-03_딸기:
2022-12-19 16:02:49,860 INFO [GH_LOG] [고도화_GH_optimization_model_load_predict.py:302] - [13864]GH Model 실행 : 임대형-04_딸기:
2022-12-19 16:02:50,022 ERROR [GH_LOG] [고도화_GH_optimization_model_load_predict.py:328] - Traceback (most recent call last):
  File "d:\theimz\조석준\NAVER_WORKS\스마트팜_혁신밸리\22년12월\모델고도화코드개발\스마트팜_혁신밸리_고도화_모델코드(전달)\고도화_GH_optimization_model_load_predict.py", line 308, in run
    df_in = GHModel.preprocess_in(self, df_in)
  File "d:\theimz\조석준\NAVER_WORKS\스마트팜_혁신밸리\22년12월\모델고도화코드개발\스마트팜_혁신밸리_고도화_모델코드(전달)\고도화_GH_optimization_model_load_predict.py", line 147, in preprocess_in
    df_in['reg_date'].iloc[i] = datetime(temp.year, temp.month, temp.day, temp.hour, (temp.minute - temp.minute % 10))
  File "C:\Anaconda3\envs\tf_env\lib\site-packages\pandas\core\indexing.py", line 713, in __setitem__
    self._has_valid_setitem_indexer(key)
  File "C:\Anaconda3\envs\tf_env\lib\site-packages\pandas\core\indexing.py", line 1413, in _has_valid_setitem_indexer
    raise IndexError("iloc cannot enlarge its target object")
IndexError: iloc cannot enlarge its target object

2022-12-19 16:02:50,024 ERROR [GH_LOG] [고도화_GH_optimization_model_load_predict.py:329] - * 모듈 실행중 오류 발생 : iloc cannot enlarge its target object
2022-12-19 16:02:50,036 ERROR [GH_LOG] [고도화_GH_optimization_model_load_predict.py:328] - Traceback (most recent call last):
  File "d:\theimz\조석준\NAVER_WORKS\스마트팜_혁신밸리\22년12월\모델고도화코드개발\스마트팜_혁신밸리_고도화_모델코드(전달)\고도화_GH_optimization_model_load_predict.py", line 308, in run
    df_in = GHModel.preprocess_in(self, df_in)
  File "d:\theimz\조석준\NAVER_WORKS\스마트팜_혁신밸리\22년12월\모델고도화코드개발\스마트팜_혁신밸리_고도화_모델코드(전달)\고도화_GH_optimization_model_load_predict.py", line 147, in preprocess_in
    df_in['reg_date'].iloc[i] = datetime(temp.year, temp.month, temp.day, temp.hour, (temp.minute - temp.minute % 10))
  File "C:\Anaconda3\envs\tf_env\lib\site-packages\pandas\core\indexing.py", line 713, in __setitem__
    self._has_valid_setitem_indexer(key)
  File "C:\Anaconda3\envs\tf_env\lib\site-packages\pandas\core\indexing.py", line 1413, in _has_valid_setitem_indexer
    raise IndexError("iloc cannot enlarge its target object")
IndexError: iloc cannot enlarge its target object

2022-12-19 16:02:50,038 ERROR [GH_LOG] [고도화_GH_optimization_model_load_predict.py:329] - * 모듈 실행중 오류 발생 : iloc cannot enlarge its target object
2022-12-19 16:02:54,893 ERROR [GH_LOG] [고도화_GH_optimization_model_load_predict.py:255] - 예측하기 오류 발생
2022-12-19 16:02:54,894 ERROR [GH_LOG] [고도화_GH_optimization_model_load_predict.py:328] - Traceback (most recent call last):
  File "d:\theimz\조석준\NAVER_WORKS\스마트팜_혁신밸리\22년12월\모델고도화코드개발\스마트팜_혁신밸리_고도화_모델코드(전달)\고도화_GH_optimization_model_load_predict.py", line 320, in run
    pridict_result, prd_date = GHModel.pridict_model(self, df)
TypeError: cannot unpack non-iterable NoneType object

2022-12-19 16:02:54,895 ERROR [GH_LOG] [고도화_GH_optimization_model_load_predict.py:329] - * 모듈 실행중 오류 발생 : cannot unpack non-iterable NoneType object
2022-12-19 16:02:54,974 ERROR [GH_LOG] [고도화_GH_optimization_model_load_predict.py:255] - 예측하기 오류 발생
2022-12-19 16:02:54,975 ERROR [GH_LOG] [고도화_GH_optimization_model_load_predict.py:328] - Traceback (most recent call last):
  File "d:\theimz\조석준\NAVER_WORKS\스마트팜_혁신밸리\22년12월\모델고도화코드개발\스마트팜_혁신밸리_고도화_모델코드(전달)\고도화_GH_optimization_model_load_predict.py", line 320, in run
    pridict_result, prd_date = GHModel.pridict_model(self, df)
TypeError: cannot unpack non-iterable NoneType object

2022-12-19 16:02:54,976 ERROR [GH_LOG] [고도화_GH_optimization_model_load_predict.py:329] - * 모듈 실행중 오류 발생 : cannot unpack non-iterable NoneType object
2022-12-19 16:02:55,573 INFO [GH_LOG] [고도화_GH_optimization_model_load_predict.py:369] - ** 모듈 실행 완료 > 총 실행시간 : 0:00:12.495029
2022-12-19 16:03:58,875 INFO [GH_LOG] [고도화_GH_optimization_model_load_predict.py:337] - GH optimization model : Start
2022-12-19 16:04:05,154 INFO [GH_LOG] [고도화_GH_optimization_model_load_predict.py:302] - [26196]GH Model 실행 : 경영형-01_딸기:
2022-12-19 16:04:05,192 INFO [GH_LOG] [고도화_GH_optimization_model_load_predict.py:302] - [38792]GH Model 실행 : 교육형-01_딸기:
2022-12-19 16:04:05,363 INFO [GH_LOG] [고도화_GH_optimization_model_load_predict.py:302] - [37136]GH Model 실행 : 임대형-01_딸기:
2022-12-19 16:04:05,368 INFO [GH_LOG] [고도화_GH_optimization_model_load_predict.py:302] - [42480]GH Model 실행 : 임대형-02_딸기:
2022-12-19 16:04:05,604 ERROR [GH_LOG] [고도화_GH_optimization_model_load_predict.py:328] - Traceback (most recent call last):
  File "d:\theimz\조석준\NAVER_WORKS\스마트팜_혁신밸리\22년12월\모델고도화코드개발\스마트팜_혁신밸리_고도화_모델코드(전달)\고도화_GH_optimization_model_load_predict.py", line 308, in run
    df_in = GHModel.preprocess_in(self, df_in)
  File "d:\theimz\조석준\NAVER_WORKS\스마트팜_혁신밸리\22년12월\모델고도화코드개발\스마트팜_혁신밸리_고도화_모델코드(전달)\고도화_GH_optimization_model_load_predict.py", line 147, in preprocess_in
    df_in['reg_date'].iloc[i] = datetime(temp.year, temp.month, temp.day, temp.hour, (temp.minute - temp.minute % 10))
  File "C:\Anaconda3\envs\tf_env\lib\site-packages\pandas\core\indexing.py", line 713, in __setitem__
    self._has_valid_setitem_indexer(key)
  File "C:\Anaconda3\envs\tf_env\lib\site-packages\pandas\core\indexing.py", line 1413, in _has_valid_setitem_indexer
    raise IndexError("iloc cannot enlarge its target object")
IndexError: iloc cannot enlarge its target object

2022-12-19 16:04:05,606 ERROR [GH_LOG] [고도화_GH_optimization_model_load_predict.py:329] - * 모듈 실행중 오류 발생 : iloc cannot enlarge its target object
2022-12-19 16:04:05,607 INFO [GH_LOG] [고도화_GH_optimization_model_load_predict.py:302] - [42480]GH Model 실행 : 임대형-03_딸기:
2022-12-19 16:04:05,637 ERROR [GH_LOG] [고도화_GH_optimization_model_load_predict.py:328] - Traceback (most recent call last):
  File "d:\theimz\조석준\NAVER_WORKS\스마트팜_혁신밸리\22년12월\모델고도화코드개발\스마트팜_혁신밸리_고도화_모델코드(전달)\고도화_GH_optimization_model_load_predict.py", line 308, in run
    df_in = GHModel.preprocess_in(self, df_in)
  File "d:\theimz\조석준\NAVER_WORKS\스마트팜_혁신밸리\22년12월\모델고도화코드개발\스마트팜_혁신밸리_고도화_모델코드(전달)\고도화_GH_optimization_model_load_predict.py", line 147, in preprocess_in
    df_in['reg_date'].iloc[i] = datetime(temp.year, temp.month, temp.day, temp.hour, (temp.minute - temp.minute % 10))
  File "C:\Anaconda3\envs\tf_env\lib\site-packages\pandas\core\indexing.py", line 713, in __setitem__
    self._has_valid_setitem_indexer(key)
  File "C:\Anaconda3\envs\tf_env\lib\site-packages\pandas\core\indexing.py", line 1413, in _has_valid_setitem_indexer
    raise IndexError("iloc cannot enlarge its target object")
IndexError: iloc cannot enlarge its target object

2022-12-19 16:04:05,639 ERROR [GH_LOG] [고도화_GH_optimization_model_load_predict.py:329] - * 모듈 실행중 오류 발생 : iloc cannot enlarge its target object
2022-12-19 16:04:05,640 INFO [GH_LOG] [고도화_GH_optimization_model_load_predict.py:302] - [37136]GH Model 실행 : 임대형-04_딸기:
2022-12-19 16:04:05,806 ERROR [GH_LOG] [고도화_GH_optimization_model_load_predict.py:328] - Traceback (most recent call last):
  File "d:\theimz\조석준\NAVER_WORKS\스마트팜_혁신밸리\22년12월\모델고도화코드개발\스마트팜_혁신밸리_고도화_모델코드(전달)\고도화_GH_optimization_model_load_predict.py", line 308, in run
    df_in = GHModel.preprocess_in(self, df_in)
  File "d:\theimz\조석준\NAVER_WORKS\스마트팜_혁신밸리\22년12월\모델고도화코드개발\스마트팜_혁신밸리_고도화_모델코드(전달)\고도화_GH_optimization_model_load_predict.py", line 147, in preprocess_in
    df_in['reg_date'].iloc[i] = datetime(temp.year, temp.month, temp.day, temp.hour, (temp.minute - temp.minute % 10))
  File "C:\Anaconda3\envs\tf_env\lib\site-packages\pandas\core\indexing.py", line 713, in __setitem__
    self._has_valid_setitem_indexer(key)
  File "C:\Anaconda3\envs\tf_env\lib\site-packages\pandas\core\indexing.py", line 1413, in _has_valid_setitem_indexer
    raise IndexError("iloc cannot enlarge its target object")
IndexError: iloc cannot enlarge its target object

2022-12-19 16:04:05,808 ERROR [GH_LOG] [고도화_GH_optimization_model_load_predict.py:329] - * 모듈 실행중 오류 발생 : iloc cannot enlarge its target object
2022-12-19 16:04:05,825 ERROR [GH_LOG] [고도화_GH_optimization_model_load_predict.py:328] - Traceback (most recent call last):
  File "d:\theimz\조석준\NAVER_WORKS\스마트팜_혁신밸리\22년12월\모델고도화코드개발\스마트팜_혁신밸리_고도화_모델코드(전달)\고도화_GH_optimization_model_load_predict.py", line 308, in run
    df_in = GHModel.preprocess_in(self, df_in)
  File "d:\theimz\조석준\NAVER_WORKS\스마트팜_혁신밸리\22년12월\모델고도화코드개발\스마트팜_혁신밸리_고도화_모델코드(전달)\고도화_GH_optimization_model_load_predict.py", line 147, in preprocess_in
    df_in['reg_date'].iloc[i] = datetime(temp.year, temp.month, temp.day, temp.hour, (temp.minute - temp.minute % 10))
  File "C:\Anaconda3\envs\tf_env\lib\site-packages\pandas\core\indexing.py", line 713, in __setitem__
    self._has_valid_setitem_indexer(key)
  File "C:\Anaconda3\envs\tf_env\lib\site-packages\pandas\core\indexing.py", line 1413, in _has_valid_setitem_indexer
    raise IndexError("iloc cannot enlarge its target object")
IndexError: iloc cannot enlarge its target object

2022-12-19 16:04:05,827 ERROR [GH_LOG] [고도화_GH_optimization_model_load_predict.py:329] - * 모듈 실행중 오류 발생 : iloc cannot enlarge its target object
2022-12-19 16:04:10,338 ERROR [GH_LOG] [고도화_GH_optimization_model_load_predict.py:55] - Traceback (most recent call last):
  File "d:\theimz\조석준\NAVER_WORKS\스마트팜_혁신밸리\22년12월\모델고도화코드개발\스마트팜_혁신밸리_고도화_모델코드(전달)\고도화_GH_optimization_model_load_predict.py", line 49, in scaling_make_dataset
    X_scaler = load(open('D:/theimz/조석준/NAVER_WORKS/스마트팜_혁신밸리/22년12월/1129이후사장님_피드백/모델고도화코드개발/상주_'+self.crop_nm+'_스케일러_AIC/상주_'+self.crop_nm+'_스케일러_AIC_'+i+'.pkl', 'rb'))
FileNotFoundError: [Errno 2] No such file or directory: 'D:/theimz/조석준/NAVER_WORKS/스마트팜_혁신밸리/22년12월/1129이후사장님_피드백/모델고도화코드개발/상주_딸기_스케일러_AIC/상주_딸기_스케일러_AIC_sky_window.pkl'

2022-12-19 16:04:10,339 ERROR [root] [고도화_GH_optimization_model_load_predict.py:56] - train 데이터셋 만드는 중 오류 발생
2022-12-19 16:04:10,357 ERROR [GH_LOG] [고도화_GH_optimization_model_load_predict.py:255] - 예측하기 오류 발생
2022-12-19 16:04:10,358 ERROR [GH_LOG] [고도화_GH_optimization_model_load_predict.py:328] - Traceback (most recent call last):
  File "d:\theimz\조석준\NAVER_WORKS\스마트팜_혁신밸리\22년12월\모델고도화코드개발\스마트팜_혁신밸리_고도화_모델코드(전달)\고도화_GH_optimization_model_load_predict.py", line 320, in run
    pridict_result, prd_date = GHModel.pridict_model(self, df)
TypeError: cannot unpack non-iterable NoneType object

2022-12-19 16:04:10,359 ERROR [GH_LOG] [고도화_GH_optimization_model_load_predict.py:329] - * 모듈 실행중 오류 발생 : cannot unpack non-iterable NoneType object
2022-12-19 16:04:10,579 ERROR [GH_LOG] [고도화_GH_optimization_model_load_predict.py:55] - Traceback (most recent call last):
  File "d:\theimz\조석준\NAVER_WORKS\스마트팜_혁신밸리\22년12월\모델고도화코드개발\스마트팜_혁신밸리_고도화_모델코드(전달)\고도화_GH_optimization_model_load_predict.py", line 49, in scaling_make_dataset
    X_scaler = load(open('D:/theimz/조석준/NAVER_WORKS/스마트팜_혁신밸리/22년12월/1129이후사장님_피드백/모델고도화코드개발/상주_'+self.crop_nm+'_스케일러_AIC/상주_'+self.crop_nm+'_스케일러_AIC_'+i+'.pkl', 'rb'))
FileNotFoundError: [Errno 2] No such file or directory: 'D:/theimz/조석준/NAVER_WORKS/스마트팜_혁신밸리/22년12월/1129이후사장님_피드백/모델고도화코드개발/상주_딸기_스케일러_AIC/상주_딸기_스케일러_AIC_sky_window.pkl'

2022-12-19 16:04:10,580 ERROR [root] [고도화_GH_optimization_model_load_predict.py:56] - train 데이터셋 만드는 중 오류 발생
2022-12-19 16:04:10,583 ERROR [GH_LOG] [고도화_GH_optimization_model_load_predict.py:255] - 예측하기 오류 발생
2022-12-19 16:04:10,584 ERROR [GH_LOG] [고도화_GH_optimization_model_load_predict.py:328] - Traceback (most recent call last):
  File "d:\theimz\조석준\NAVER_WORKS\스마트팜_혁신밸리\22년12월\모델고도화코드개발\스마트팜_혁신밸리_고도화_모델코드(전달)\고도화_GH_optimization_model_load_predict.py", line 320, in run
    pridict_result, prd_date = GHModel.pridict_model(self, df)
TypeError: cannot unpack non-iterable NoneType object

2022-12-19 16:04:10,585 ERROR [GH_LOG] [고도화_GH_optimization_model_load_predict.py:329] - * 모듈 실행중 오류 발생 : cannot unpack non-iterable NoneType object
2022-12-19 16:04:11,193 INFO [GH_LOG] [고도화_GH_optimization_model_load_predict.py:369] - ** 모듈 실행 완료 > 총 실행시간 : 0:00:12.318010
2022-12-19 16:08:20,815 INFO [GH_LOG] [고도화_GH_optimization_model_load_predict.py:337] - GH optimization model : Start
2022-12-19 16:08:26,922 INFO [GH_LOG] [고도화_GH_optimization_model_load_predict.py:302] - [13416]GH Model 실행 : 경영형-01_딸기:
2022-12-19 16:08:26,953 INFO [GH_LOG] [고도화_GH_optimization_model_load_predict.py:302] - [10772]GH Model 실행 : 교육형-01_딸기:
2022-12-19 16:08:27,039 INFO [GH_LOG] [고도화_GH_optimization_model_load_predict.py:302] - [31860]GH Model 실행 : 임대형-01_딸기:
2022-12-19 16:08:27,045 INFO [GH_LOG] [고도화_GH_optimization_model_load_predict.py:302] - [25440]GH Model 실행 : 임대형-02_딸기:
2022-12-19 16:08:27,220 ERROR [GH_LOG] [고도화_GH_optimization_model_load_predict.py:328] - Traceback (most recent call last):
  File "d:\theimz\조석준\NAVER_WORKS\스마트팜_혁신밸리\22년12월\모델고도화코드개발\스마트팜_혁신밸리_고도화_모델코드(전달)\고도화_GH_optimization_model_load_predict.py", line 308, in run
    df_in = GHModel.preprocess_in(self, df_in)
  File "d:\theimz\조석준\NAVER_WORKS\스마트팜_혁신밸리\22년12월\모델고도화코드개발\스마트팜_혁신밸리_고도화_모델코드(전달)\고도화_GH_optimization_model_load_predict.py", line 147, in preprocess_in
    df_in['reg_date'].iloc[i] = datetime(temp.year, temp.month, temp.day, temp.hour, (temp.minute - temp.minute % 10))
  File "C:\Anaconda3\envs\tf_env\lib\site-packages\pandas\core\indexing.py", line 713, in __setitem__
    self._has_valid_setitem_indexer(key)
  File "C:\Anaconda3\envs\tf_env\lib\site-packages\pandas\core\indexing.py", line 1413, in _has_valid_setitem_indexer
    raise IndexError("iloc cannot enlarge its target object")
IndexError: iloc cannot enlarge its target object

2022-12-19 16:08:27,221 ERROR [GH_LOG] [고도화_GH_optimization_model_load_predict.py:328] - Traceback (most recent call last):
  File "d:\theimz\조석준\NAVER_WORKS\스마트팜_혁신밸리\22년12월\모델고도화코드개발\스마트팜_혁신밸리_고도화_모델코드(전달)\고도화_GH_optimization_model_load_predict.py", line 308, in run
    df_in = GHModel.preprocess_in(self, df_in)
  File "d:\theimz\조석준\NAVER_WORKS\스마트팜_혁신밸리\22년12월\모델고도화코드개발\스마트팜_혁신밸리_고도화_모델코드(전달)\고도화_GH_optimization_model_load_predict.py", line 147, in preprocess_in
    df_in['reg_date'].iloc[i] = datetime(temp.year, temp.month, temp.day, temp.hour, (temp.minute - temp.minute % 10))
  File "C:\Anaconda3\envs\tf_env\lib\site-packages\pandas\core\indexing.py", line 713, in __setitem__
    self._has_valid_setitem_indexer(key)
  File "C:\Anaconda3\envs\tf_env\lib\site-packages\pandas\core\indexing.py", line 1413, in _has_valid_setitem_indexer
    raise IndexError("iloc cannot enlarge its target object")
IndexError: iloc cannot enlarge its target object

2022-12-19 16:08:27,222 ERROR [GH_LOG] [고도화_GH_optimization_model_load_predict.py:329] - * 모듈 실행중 오류 발생 : iloc cannot enlarge its target object
2022-12-19 16:08:27,223 ERROR [GH_LOG] [고도화_GH_optimization_model_load_predict.py:329] - * 모듈 실행중 오류 발생 : iloc cannot enlarge its target object
2022-12-19 16:08:27,224 INFO [GH_LOG] [고도화_GH_optimization_model_load_predict.py:302] - [25440]GH Model 실행 : 임대형-03_딸기:
2022-12-19 16:08:27,224 INFO [GH_LOG] [고도화_GH_optimization_model_load_predict.py:302] - [31860]GH Model 실행 : 임대형-04_딸기:
2022-12-19 16:08:27,406 ERROR [GH_LOG] [고도화_GH_optimization_model_load_predict.py:328] - Traceback (most recent call last):
  File "d:\theimz\조석준\NAVER_WORKS\스마트팜_혁신밸리\22년12월\모델고도화코드개발\스마트팜_혁신밸리_고도화_모델코드(전달)\고도화_GH_optimization_model_load_predict.py", line 308, in run
    df_in = GHModel.preprocess_in(self, df_in)
  File "d:\theimz\조석준\NAVER_WORKS\스마트팜_혁신밸리\22년12월\모델고도화코드개발\스마트팜_혁신밸리_고도화_모델코드(전달)\고도화_GH_optimization_model_load_predict.py", line 147, in preprocess_in
    df_in['reg_date'].iloc[i] = datetime(temp.year, temp.month, temp.day, temp.hour, (temp.minute - temp.minute % 10))
  File "C:\Anaconda3\envs\tf_env\lib\site-packages\pandas\core\indexing.py", line 713, in __setitem__
    self._has_valid_setitem_indexer(key)
  File "C:\Anaconda3\envs\tf_env\lib\site-packages\pandas\core\indexing.py", line 1413, in _has_valid_setitem_indexer
    raise IndexError("iloc cannot enlarge its target object")
IndexError: iloc cannot enlarge its target object

2022-12-19 16:08:27,408 ERROR [GH_LOG] [고도화_GH_optimization_model_load_predict.py:329] - * 모듈 실행중 오류 발생 : iloc cannot enlarge its target object
2022-12-19 16:08:27,781 ERROR [GH_LOG] [고도화_GH_optimization_model_load_predict.py:328] - Traceback (most recent call last):
  File "d:\theimz\조석준\NAVER_WORKS\스마트팜_혁신밸리\22년12월\모델고도화코드개발\스마트팜_혁신밸리_고도화_모델코드(전달)\고도화_GH_optimization_model_load_predict.py", line 308, in run
    df_in = GHModel.preprocess_in(self, df_in)
  File "d:\theimz\조석준\NAVER_WORKS\스마트팜_혁신밸리\22년12월\모델고도화코드개발\스마트팜_혁신밸리_고도화_모델코드(전달)\고도화_GH_optimization_model_load_predict.py", line 147, in preprocess_in
    df_in['reg_date'].iloc[i] = datetime(temp.year, temp.month, temp.day, temp.hour, (temp.minute - temp.minute % 10))
  File "C:\Anaconda3\envs\tf_env\lib\site-packages\pandas\core\indexing.py", line 713, in __setitem__
    self._has_valid_setitem_indexer(key)
  File "C:\Anaconda3\envs\tf_env\lib\site-packages\pandas\core\indexing.py", line 1413, in _has_valid_setitem_indexer
    raise IndexError("iloc cannot enlarge its target object")
IndexError: iloc cannot enlarge its target object

2022-12-19 16:08:27,782 ERROR [GH_LOG] [고도화_GH_optimization_model_load_predict.py:329] - * 모듈 실행중 오류 발생 : iloc cannot enlarge its target object
2022-12-19 16:08:32,658 ERROR [GH_LOG] [고도화_GH_optimization_model_load_predict.py:255] - 예측하기 오류 발생
2022-12-19 16:08:32,659 ERROR [GH_LOG] [고도화_GH_optimization_model_load_predict.py:328] - Traceback (most recent call last):
  File "d:\theimz\조석준\NAVER_WORKS\스마트팜_혁신밸리\22년12월\모델고도화코드개발\스마트팜_혁신밸리_고도화_모델코드(전달)\고도화_GH_optimization_model_load_predict.py", line 320, in run
    pridict_result, prd_date = GHModel.pridict_model(self, df)
TypeError: cannot unpack non-iterable NoneType object

2022-12-19 16:08:32,659 ERROR [GH_LOG] [고도화_GH_optimization_model_load_predict.py:329] - * 모듈 실행중 오류 발생 : cannot unpack non-iterable NoneType object
2022-12-19 16:08:33,279 ERROR [GH_LOG] [고도화_GH_optimization_model_load_predict.py:255] - 예측하기 오류 발생
2022-12-19 16:08:33,280 ERROR [GH_LOG] [고도화_GH_optimization_model_load_predict.py:328] - Traceback (most recent call last):
  File "d:\theimz\조석준\NAVER_WORKS\스마트팜_혁신밸리\22년12월\모델고도화코드개발\스마트팜_혁신밸리_고도화_모델코드(전달)\고도화_GH_optimization_model_load_predict.py", line 320, in run
    pridict_result, prd_date = GHModel.pridict_model(self, df)
TypeError: cannot unpack non-iterable NoneType object

2022-12-19 16:08:33,280 ERROR [GH_LOG] [고도화_GH_optimization_model_load_predict.py:329] - * 모듈 실행중 오류 발생 : cannot unpack non-iterable NoneType object
2022-12-19 16:08:33,886 INFO [GH_LOG] [고도화_GH_optimization_model_load_predict.py:369] - ** 모듈 실행 완료 > 총 실행시간 : 0:00:13.070000
2022-12-19 16:17:06,017 INFO [GH_LOG] [고도화_GH_optimization_model_load_predict.py:338] - GH optimization model : Start
2022-12-19 16:17:12,472 INFO [GH_LOG] [고도화_GH_optimization_model_load_predict.py:303] - [22512]GH Model 실행 : 경영형-01_딸기:
2022-12-19 16:17:12,558 INFO [GH_LOG] [고도화_GH_optimization_model_load_predict.py:303] - [30072]GH Model 실행 : 교육형-01_딸기:
2022-12-19 16:17:12,565 INFO [GH_LOG] [고도화_GH_optimization_model_load_predict.py:303] - [32592]GH Model 실행 : 임대형-01_딸기:
2022-12-19 16:17:12,582 INFO [GH_LOG] [고도화_GH_optimization_model_load_predict.py:303] - [41096]GH Model 실행 : 임대형-02_딸기:
2022-12-19 16:17:12,747 ERROR [GH_LOG] [고도화_GH_optimization_model_load_predict.py:329] - Traceback (most recent call last):
  File "d:\theimz\조석준\NAVER_WORKS\스마트팜_혁신밸리\22년12월\모델고도화코드개발\스마트팜_혁신밸리_고도화_모델코드(전달)\고도화_GH_optimization_model_load_predict.py", line 310, in run
    if df_in is None or df_in.empty: raise Exception("데이터 전처리 및 병합 오류 발생")
Exception: 데이터 전처리 및 병합 오류 발생

2022-12-19 16:17:12,748 ERROR [GH_LOG] [고도화_GH_optimization_model_load_predict.py:330] - * 모듈 실행중 오류 발생 : 데이터 전처리 및 병합 오류 발생
2022-12-19 16:17:12,749 INFO [GH_LOG] [고도화_GH_optimization_model_load_predict.py:303] - [32592]GH Model 실행 : 임대형-03_딸기:
2022-12-19 16:17:12,879 ERROR [GH_LOG] [고도화_GH_optimization_model_load_predict.py:329] - Traceback (most recent call last):
  File "d:\theimz\조석준\NAVER_WORKS\스마트팜_혁신밸리\22년12월\모델고도화코드개발\스마트팜_혁신밸리_고도화_모델코드(전달)\고도화_GH_optimization_model_load_predict.py", line 310, in run
    if df_in is None or df_in.empty: raise Exception("데이터 전처리 및 병합 오류 발생")
Exception: 데이터 전처리 및 병합 오류 발생

2022-12-19 16:17:12,880 ERROR [GH_LOG] [고도화_GH_optimization_model_load_predict.py:330] - * 모듈 실행중 오류 발생 : 데이터 전처리 및 병합 오류 발생
2022-12-19 16:17:12,881 INFO [GH_LOG] [고도화_GH_optimization_model_load_predict.py:303] - [41096]GH Model 실행 : 임대형-04_딸기:
2022-12-19 16:17:12,941 ERROR [GH_LOG] [고도화_GH_optimization_model_load_predict.py:329] - Traceback (most recent call last):
  File "d:\theimz\조석준\NAVER_WORKS\스마트팜_혁신밸리\22년12월\모델고도화코드개발\스마트팜_혁신밸리_고도화_모델코드(전달)\고도화_GH_optimization_model_load_predict.py", line 310, in run
    if df_in is None or df_in.empty: raise Exception("데이터 전처리 및 병합 오류 발생")
Exception: 데이터 전처리 및 병합 오류 발생

2022-12-19 16:17:12,942 ERROR [GH_LOG] [고도화_GH_optimization_model_load_predict.py:330] - * 모듈 실행중 오류 발생 : 데이터 전처리 및 병합 오류 발생
2022-12-19 16:17:13,056 ERROR [GH_LOG] [고도화_GH_optimization_model_load_predict.py:329] - Traceback (most recent call last):
  File "d:\theimz\조석준\NAVER_WORKS\스마트팜_혁신밸리\22년12월\모델고도화코드개발\스마트팜_혁신밸리_고도화_모델코드(전달)\고도화_GH_optimization_model_load_predict.py", line 310, in run
    if df_in is None or df_in.empty: raise Exception("데이터 전처리 및 병합 오류 발생")
Exception: 데이터 전처리 및 병합 오류 발생

2022-12-19 16:17:13,057 ERROR [GH_LOG] [고도화_GH_optimization_model_load_predict.py:330] - * 모듈 실행중 오류 발생 : 데이터 전처리 및 병합 오류 발생
2022-12-19 16:19:34,169 INFO [GH_LOG] [고도화_GH_optimization_model_load_predict.py:341] - GH optimization model : Start
2022-12-19 16:19:40,670 INFO [GH_LOG] [고도화_GH_optimization_model_load_predict.py:306] - [15164]GH Model 실행 : 경영형-01_딸기:
2022-12-19 16:19:40,670 INFO [GH_LOG] [고도화_GH_optimization_model_load_predict.py:306] - [26412]GH Model 실행 : 교육형-01_딸기:
2022-12-19 16:19:40,718 INFO [GH_LOG] [고도화_GH_optimization_model_load_predict.py:306] - [9352]GH Model 실행 : 임대형-01_딸기:
2022-12-19 16:19:40,737 INFO [GH_LOG] [고도화_GH_optimization_model_load_predict.py:306] - [38500]GH Model 실행 : 임대형-02_딸기:
2022-12-19 16:19:40,914 ERROR [GH_LOG] [고도화_GH_optimization_model_load_predict.py:332] - Traceback (most recent call last):
  File "d:\theimz\조석준\NAVER_WORKS\스마트팜_혁신밸리\22년12월\모델고도화코드개발\스마트팜_혁신밸리_고도화_모델코드(전달)\고도화_GH_optimization_model_load_predict.py", line 313, in run
    if df_in is None or df_in.empty: raise Exception("데이터 전처리 및 병합 오류 발생")
Exception: 데이터 전처리 및 병합 오류 발생

2022-12-19 16:19:40,914 ERROR [GH_LOG] [고도화_GH_optimization_model_load_predict.py:332] - Traceback (most recent call last):
  File "d:\theimz\조석준\NAVER_WORKS\스마트팜_혁신밸리\22년12월\모델고도화코드개발\스마트팜_혁신밸리_고도화_모델코드(전달)\고도화_GH_optimization_model_load_predict.py", line 313, in run
    if df_in is None or df_in.empty: raise Exception("데이터 전처리 및 병합 오류 발생")
Exception: 데이터 전처리 및 병합 오류 발생

2022-12-19 16:19:40,915 ERROR [GH_LOG] [고도화_GH_optimization_model_load_predict.py:333] - * 모듈 실행중 오류 발생 : 데이터 전처리 및 병합 오류 발생
2022-12-19 16:19:40,915 ERROR [GH_LOG] [고도화_GH_optimization_model_load_predict.py:333] - * 모듈 실행중 오류 발생 : 데이터 전처리 및 병합 오류 발생
2022-12-19 16:19:40,916 INFO [GH_LOG] [고도화_GH_optimization_model_load_predict.py:306] - [9352]GH Model 실행 : 임대형-03_딸기:
2022-12-19 16:19:40,916 INFO [GH_LOG] [고도화_GH_optimization_model_load_predict.py:306] - [38500]GH Model 실행 : 임대형-04_딸기:
2022-12-19 16:19:41,094 ERROR [GH_LOG] [고도화_GH_optimization_model_load_predict.py:332] - Traceback (most recent call last):
  File "d:\theimz\조석준\NAVER_WORKS\스마트팜_혁신밸리\22년12월\모델고도화코드개발\스마트팜_혁신밸리_고도화_모델코드(전달)\고도화_GH_optimization_model_load_predict.py", line 313, in run
    if df_in is None or df_in.empty: raise Exception("데이터 전처리 및 병합 오류 발생")
Exception: 데이터 전처리 및 병합 오류 발생

2022-12-19 16:19:41,095 ERROR [GH_LOG] [고도화_GH_optimization_model_load_predict.py:333] - * 모듈 실행중 오류 발생 : 데이터 전처리 및 병합 오류 발생
2022-12-19 16:19:41,586 ERROR [GH_LOG] [고도화_GH_optimization_model_load_predict.py:332] - Traceback (most recent call last):
  File "d:\theimz\조석준\NAVER_WORKS\스마트팜_혁신밸리\22년12월\모델고도화코드개발\스마트팜_혁신밸리_고도화_모델코드(전달)\고도화_GH_optimization_model_load_predict.py", line 313, in run
    if df_in is None or df_in.empty: raise Exception("데이터 전처리 및 병합 오류 발생")
Exception: 데이터 전처리 및 병합 오류 발생

2022-12-19 16:19:41,587 ERROR [GH_LOG] [고도화_GH_optimization_model_load_predict.py:333] - * 모듈 실행중 오류 발생 : 데이터 전처리 및 병합 오류 발생
2022-12-19 16:20:20,641 INFO [GH_LOG] [고도화_GH_optimization_model_load_predict.py:341] - GH optimization model : Start
2022-12-19 16:20:26,958 INFO [GH_LOG] [고도화_GH_optimization_model_load_predict.py:306] - [39472]GH Model 실행 : 경영형-01_딸기:
2022-12-19 16:20:26,968 INFO [GH_LOG] [고도화_GH_optimization_model_load_predict.py:306] - [21528]GH Model 실행 : 교육형-01_딸기:
2022-12-19 16:20:27,117 INFO [GH_LOG] [고도화_GH_optimization_model_load_predict.py:306] - [30444]GH Model 실행 : 임대형-01_딸기:
2022-12-19 16:20:27,117 INFO [GH_LOG] [고도화_GH_optimization_model_load_predict.py:306] - [30412]GH Model 실행 : 임대형-02_딸기:
2022-12-19 16:20:31,990 ERROR [GH_LOG] [고도화_GH_optimization_model_load_predict.py:332] - Traceback (most recent call last):
  File "d:\theimz\조석준\NAVER_WORKS\스마트팜_혁신밸리\22년12월\모델고도화코드개발\스마트팜_혁신밸리_고도화_모델코드(전달)\고도화_GH_optimization_model_load_predict.py", line 319, in run
    if df is None or df.empty: raise Exception("데이터 전처리 및 병합 오류 발생")
Exception: 데이터 전처리 및 병합 오류 발생

2022-12-19 16:20:31,991 ERROR [GH_LOG] [고도화_GH_optimization_model_load_predict.py:333] - * 모듈 실행중 오류 발생 : 데이터 전처리 및 병합 오류 발생
2022-12-19 16:20:31,992 INFO [GH_LOG] [고도화_GH_optimization_model_load_predict.py:306] - [30444]GH Model 실행 : 임대형-03_딸기:
2022-12-19 16:20:32,416 ERROR [GH_LOG] [고도화_GH_optimization_model_load_predict.py:332] - Traceback (most recent call last):
  File "d:\theimz\조석준\NAVER_WORKS\스마트팜_혁신밸리\22년12월\모델고도화코드개발\스마트팜_혁신밸리_고도화_모델코드(전달)\고도화_GH_optimization_model_load_predict.py", line 319, in run
    if df is None or df.empty: raise Exception("데이터 전처리 및 병합 오류 발생")
Exception: 데이터 전처리 및 병합 오류 발생

2022-12-19 16:20:32,417 ERROR [GH_LOG] [고도화_GH_optimization_model_load_predict.py:333] - * 모듈 실행중 오류 발생 : 데이터 전처리 및 병합 오류 발생
2022-12-19 16:20:32,418 INFO [GH_LOG] [고도화_GH_optimization_model_load_predict.py:306] - [30412]GH Model 실행 : 임대형-04_딸기:
2022-12-19 16:20:33,616 ERROR [GH_LOG] [고도화_GH_optimization_model_load_predict.py:259] - 예측하기 오류 발생
2022-12-19 16:20:33,617 ERROR [GH_LOG] [고도화_GH_optimization_model_load_predict.py:332] - Traceback (most recent call last):
  File "d:\theimz\조석준\NAVER_WORKS\스마트팜_혁신밸리\22년12월\모델고도화코드개발\스마트팜_혁신밸리_고도화_모델코드(전달)\고도화_GH_optimization_model_load_predict.py", line 324, in run
    pridict_result, prd_date = GHModel.pridict_model(self, df)
TypeError: cannot unpack non-iterable NoneType object

2022-12-19 16:20:33,617 ERROR [GH_LOG] [고도화_GH_optimization_model_load_predict.py:333] - * 모듈 실행중 오류 발생 : cannot unpack non-iterable NoneType object
2022-12-19 16:20:33,626 ERROR [GH_LOG] [고도화_GH_optimization_model_load_predict.py:259] - 예측하기 오류 발생
2022-12-19 16:20:33,627 ERROR [GH_LOG] [고도화_GH_optimization_model_load_predict.py:332] - Traceback (most recent call last):
  File "d:\theimz\조석준\NAVER_WORKS\스마트팜_혁신밸리\22년12월\모델고도화코드개발\스마트팜_혁신밸리_고도화_모델코드(전달)\고도화_GH_optimization_model_load_predict.py", line 324, in run
    pridict_result, prd_date = GHModel.pridict_model(self, df)
TypeError: cannot unpack non-iterable NoneType object

2022-12-19 16:20:33,627 ERROR [GH_LOG] [고도화_GH_optimization_model_load_predict.py:333] - * 모듈 실행중 오류 발생 : cannot unpack non-iterable NoneType object
2022-12-19 16:20:35,270 ERROR [GH_LOG] [고도화_GH_optimization_model_load_predict.py:332] - Traceback (most recent call last):
  File "d:\theimz\조석준\NAVER_WORKS\스마트팜_혁신밸리\22년12월\모델고도화코드개발\스마트팜_혁신밸리_고도화_모델코드(전달)\고도화_GH_optimization_model_load_predict.py", line 319, in run
    if df is None or df.empty: raise Exception("데이터 전처리 및 병합 오류 발생")
Exception: 데이터 전처리 및 병합 오류 발생

2022-12-19 16:20:35,271 ERROR [GH_LOG] [고도화_GH_optimization_model_load_predict.py:333] - * 모듈 실행중 오류 발생 : 데이터 전처리 및 병합 오류 발생
2022-12-19 16:20:36,020 ERROR [GH_LOG] [고도화_GH_optimization_model_load_predict.py:332] - Traceback (most recent call last):
  File "d:\theimz\조석준\NAVER_WORKS\스마트팜_혁신밸리\22년12월\모델고도화코드개발\스마트팜_혁신밸리_고도화_모델코드(전달)\고도화_GH_optimization_model_load_predict.py", line 319, in run
    if df is None or df.empty: raise Exception("데이터 전처리 및 병합 오류 발생")
Exception: 데이터 전처리 및 병합 오류 발생

2022-12-19 16:20:36,021 ERROR [GH_LOG] [고도화_GH_optimization_model_load_predict.py:333] - * 모듈 실행중 오류 발생 : 데이터 전처리 및 병합 오류 발생
2022-12-19 16:20:36,677 INFO [GH_LOG] [고도화_GH_optimization_model_load_predict.py:373] - ** 모듈 실행 완료 > 총 실행시간 : 0:00:16.035056
2022-12-19 16:23:48,673 INFO [GH_LOG] [고도화_GH_optimization_model_load_predict.py:341] - GH optimization model : Start
2022-12-19 16:23:55,022 INFO [GH_LOG] [고도화_GH_optimization_model_load_predict.py:306] - [3860]GH Model 실행 : 경영형-01_딸기:
2022-12-19 16:23:55,022 INFO [GH_LOG] [고도화_GH_optimization_model_load_predict.py:306] - [29264]GH Model 실행 : 교육형-01_딸기:
2022-12-19 16:23:55,122 INFO [GH_LOG] [고도화_GH_optimization_model_load_predict.py:306] - [17308]GH Model 실행 : 임대형-01_딸기:
2022-12-19 16:23:55,132 INFO [GH_LOG] [고도화_GH_optimization_model_load_predict.py:306] - [27144]GH Model 실행 : 임대형-02_딸기:
2022-12-19 16:23:55,374 ERROR [GH_LOG] [고도화_GH_optimization_model_load_predict.py:332] - Traceback (most recent call last):
  File "d:\theimz\조석준\NAVER_WORKS\스마트팜_혁신밸리\22년12월\모델고도화코드개발\스마트팜_혁신밸리_고도화_모델코드(전달)\고도화_GH_optimization_model_load_predict.py", line 313, in run
    if df_in is None or df_in.empty: raise Exception("데이터 전처리 및 병합 오류 발생")
Exception: 데이터 전처리 및 병합 오류 발생

2022-12-19 16:23:55,375 ERROR [GH_LOG] [고도화_GH_optimization_model_load_predict.py:332] - Traceback (most recent call last):
  File "d:\theimz\조석준\NAVER_WORKS\스마트팜_혁신밸리\22년12월\모델고도화코드개발\스마트팜_혁신밸리_고도화_모델코드(전달)\고도화_GH_optimization_model_load_predict.py", line 313, in run
    if df_in is None or df_in.empty: raise Exception("데이터 전처리 및 병합 오류 발생")
Exception: 데이터 전처리 및 병합 오류 발생

2022-12-19 16:23:55,375 ERROR [GH_LOG] [고도화_GH_optimization_model_load_predict.py:333] - * 모듈 실행중 오류 발생 : 데이터 전처리 및 병합 오류 발생
2022-12-19 16:23:55,376 ERROR [GH_LOG] [고도화_GH_optimization_model_load_predict.py:333] - * 모듈 실행중 오류 발생 : 데이터 전처리 및 병합 오류 발생
2022-12-19 16:23:55,376 INFO [GH_LOG] [고도화_GH_optimization_model_load_predict.py:306] - [17308]GH Model 실행 : 임대형-03_딸기:
2022-12-19 16:23:55,377 INFO [GH_LOG] [고도화_GH_optimization_model_load_predict.py:306] - [27144]GH Model 실행 : 임대형-04_딸기:
2022-12-19 16:23:55,577 ERROR [GH_LOG] [고도화_GH_optimization_model_load_predict.py:332] - Traceback (most recent call last):
  File "d:\theimz\조석준\NAVER_WORKS\스마트팜_혁신밸리\22년12월\모델고도화코드개발\스마트팜_혁신밸리_고도화_모델코드(전달)\고도화_GH_optimization_model_load_predict.py", line 313, in run
    if df_in is None or df_in.empty: raise Exception("데이터 전처리 및 병합 오류 발생")
Exception: 데이터 전처리 및 병합 오류 발생

2022-12-19 16:23:55,578 ERROR [GH_LOG] [고도화_GH_optimization_model_load_predict.py:333] - * 모듈 실행중 오류 발생 : 데이터 전처리 및 병합 오류 발생
2022-12-19 16:23:55,585 ERROR [GH_LOG] [고도화_GH_optimization_model_load_predict.py:332] - Traceback (most recent call last):
  File "d:\theimz\조석준\NAVER_WORKS\스마트팜_혁신밸리\22년12월\모델고도화코드개발\스마트팜_혁신밸리_고도화_모델코드(전달)\고도화_GH_optimization_model_load_predict.py", line 313, in run
    if df_in is None or df_in.empty: raise Exception("데이터 전처리 및 병합 오류 발생")
Exception: 데이터 전처리 및 병합 오류 발생

2022-12-19 16:23:55,586 ERROR [GH_LOG] [고도화_GH_optimization_model_load_predict.py:333] - * 모듈 실행중 오류 발생 : 데이터 전처리 및 병합 오류 발생
2022-12-19 16:24:00,871 ERROR [GH_LOG] [고도화_GH_optimization_model_load_predict.py:332] - Traceback (most recent call last):
  File "d:\theimz\조석준\NAVER_WORKS\스마트팜_혁신밸리\22년12월\모델고도화코드개발\스마트팜_혁신밸리_고도화_모델코드(전달)\고도화_GH_optimization_model_load_predict.py", line 327, in run
    GHModel.export_csv(self, predicted_value, prd_date)
  File "d:\theimz\조석준\NAVER_WORKS\스마트팜_혁신밸리\22년12월\모델고도화코드개발\스마트팜_혁신밸리_고도화_모델코드(전달)\고도화_GH_optimization_model_load_predict.py", line 274, in export_csv
    GH_env_monitor.loc[0] = [0,   self.fclty_nm, self.crop_nm, predicted_value[0], 0,   0,                  predicted_value[1],
IndexError: list index out of range

2022-12-19 16:24:00,872 ERROR [GH_LOG] [고도화_GH_optimization_model_load_predict.py:333] - * 모듈 실행중 오류 발생 : list index out of range
2022-12-19 16:24:01,186 ERROR [GH_LOG] [고도화_GH_optimization_model_load_predict.py:332] - Traceback (most recent call last):
  File "d:\theimz\조석준\NAVER_WORKS\스마트팜_혁신밸리\22년12월\모델고도화코드개발\스마트팜_혁신밸리_고도화_모델코드(전달)\고도화_GH_optimization_model_load_predict.py", line 327, in run
    GHModel.export_csv(self, predicted_value, prd_date)
  File "d:\theimz\조석준\NAVER_WORKS\스마트팜_혁신밸리\22년12월\모델고도화코드개발\스마트팜_혁신밸리_고도화_모델코드(전달)\고도화_GH_optimization_model_load_predict.py", line 274, in export_csv
    GH_env_monitor.loc[0] = [0,   self.fclty_nm, self.crop_nm, predicted_value[0], 0,   0,                  predicted_value[1],
IndexError: list index out of range

2022-12-19 16:24:01,187 ERROR [GH_LOG] [고도화_GH_optimization_model_load_predict.py:333] - * 모듈 실행중 오류 발생 : list index out of range
2022-12-19 16:24:01,821 INFO [GH_LOG] [고도화_GH_optimization_model_load_predict.py:373] - ** 모듈 실행 완료 > 총 실행시간 : 0:00:13.148000
2022-12-19 16:28:44,707 INFO [GH_LOG] [고도화_GH_optimization_model_load_predict.py:346] - GH optimization model : Start
2022-12-19 16:28:51,093 INFO [GH_LOG] [고도화_GH_optimization_model_load_predict.py:311] - [1636]GH Model 실행 : 경영형-01_딸기:
2022-12-19 16:28:51,167 INFO [GH_LOG] [고도화_GH_optimization_model_load_predict.py:311] - [25160]GH Model 실행 : 교육형-01_딸기:
2022-12-19 16:28:51,231 INFO [GH_LOG] [고도화_GH_optimization_model_load_predict.py:311] - [44096]GH Model 실행 : 임대형-01_딸기:
2022-12-19 16:28:51,234 INFO [GH_LOG] [고도화_GH_optimization_model_load_predict.py:311] - [29144]GH Model 실행 : 임대형-02_딸기:
2022-12-19 16:28:56,176 ERROR [GH_LOG] [고도화_GH_optimization_model_load_predict.py:337] - Traceback (most recent call last):
  File "d:\theimz\조석준\NAVER_WORKS\스마트팜_혁신밸리\22년12월\모델고도화코드개발\스마트팜_혁신밸리_고도화_모델코드(전달)\고도화_GH_optimization_model_load_predict.py", line 324, in run
    if df is None or df.empty: raise Exception("데이터 전처리 및 병합 오류 발생")
Exception: 데이터 전처리 및 병합 오류 발생

2022-12-19 16:28:56,178 ERROR [GH_LOG] [고도화_GH_optimization_model_load_predict.py:338] - * 모듈 실행중 오류 발생 : 데이터 전처리 및 병합 오류 발생
2022-12-19 16:28:56,178 INFO [GH_LOG] [고도화_GH_optimization_model_load_predict.py:311] - [29144]GH Model 실행 : 임대형-03_딸기:
2022-12-19 16:28:56,205 ERROR [GH_LOG] [고도화_GH_optimization_model_load_predict.py:337] - Traceback (most recent call last):
  File "d:\theimz\조석준\NAVER_WORKS\스마트팜_혁신밸리\22년12월\모델고도화코드개발\스마트팜_혁신밸리_고도화_모델코드(전달)\고도화_GH_optimization_model_load_predict.py", line 324, in run
    if df is None or df.empty: raise Exception("데이터 전처리 및 병합 오류 발생")
Exception: 데이터 전처리 및 병합 오류 발생

2022-12-19 16:28:56,206 ERROR [GH_LOG] [고도화_GH_optimization_model_load_predict.py:338] - * 모듈 실행중 오류 발생 : 데이터 전처리 및 병합 오류 발생
2022-12-19 16:28:56,207 INFO [GH_LOG] [고도화_GH_optimization_model_load_predict.py:311] - [44096]GH Model 실행 : 임대형-04_딸기:
2022-12-19 16:28:58,309 ERROR [GH_LOG] [고도화_GH_optimization_model_load_predict.py:337] - Traceback (most recent call last):
  File "d:\theimz\조석준\NAVER_WORKS\스마트팜_혁신밸리\22년12월\모델고도화코드개발\스마트팜_혁신밸리_고도화_모델코드(전달)\고도화_GH_optimization_model_load_predict.py", line 332, in run
    GHModel.export_csv(self, predicted_value, prd_date)
  File "d:\theimz\조석준\NAVER_WORKS\스마트팜_혁신밸리\22년12월\모델고도화코드개발\스마트팜_혁신밸리_고도화_모델코드(전달)\고도화_GH_optimization_model_load_predict.py", line 279, in export_csv
    GH_env_monitor.loc[0] = [0,   self.fclty_nm, self.crop_nm, predicted_value[0], 0,   0,                  predicted_value[1],
IndexError: list index out of range

2022-12-19 16:28:58,310 ERROR [GH_LOG] [고도화_GH_optimization_model_load_predict.py:338] - * 모듈 실행중 오류 발생 : list index out of range
2022-12-19 16:28:58,354 ERROR [GH_LOG] [고도화_GH_optimization_model_load_predict.py:337] - Traceback (most recent call last):
  File "d:\theimz\조석준\NAVER_WORKS\스마트팜_혁신밸리\22년12월\모델고도화코드개발\스마트팜_혁신밸리_고도화_모델코드(전달)\고도화_GH_optimization_model_load_predict.py", line 332, in run
    GHModel.export_csv(self, predicted_value, prd_date)
  File "d:\theimz\조석준\NAVER_WORKS\스마트팜_혁신밸리\22년12월\모델고도화코드개발\스마트팜_혁신밸리_고도화_모델코드(전달)\고도화_GH_optimization_model_load_predict.py", line 279, in export_csv
    GH_env_monitor.loc[0] = [0,   self.fclty_nm, self.crop_nm, predicted_value[0], 0,   0,                  predicted_value[1],
IndexError: list index out of range

2022-12-19 16:28:58,356 ERROR [GH_LOG] [고도화_GH_optimization_model_load_predict.py:338] - * 모듈 실행중 오류 발생 : list index out of range
2022-12-19 16:31:26,030 INFO [GH_LOG] [고도화_GH_optimization_model_load_predict.py:347] - GH optimization model : Start
2022-12-19 16:31:32,420 INFO [GH_LOG] [고도화_GH_optimization_model_load_predict.py:312] - [34164]GH Model 실행 : 경영형-01_딸기:
2022-12-19 16:31:32,420 INFO [GH_LOG] [고도화_GH_optimization_model_load_predict.py:312] - [26540]GH Model 실행 : 교육형-01_딸기:
2022-12-19 16:31:32,494 INFO [GH_LOG] [고도화_GH_optimization_model_load_predict.py:312] - [17384]GH Model 실행 : 임대형-01_딸기:
2022-12-19 16:31:32,495 INFO [GH_LOG] [고도화_GH_optimization_model_load_predict.py:312] - [40916]GH Model 실행 : 임대형-02_딸기:
2022-12-19 16:31:37,702 ERROR [GH_LOG] [고도화_GH_optimization_model_load_predict.py:338] - Traceback (most recent call last):
  File "d:\theimz\조석준\NAVER_WORKS\스마트팜_혁신밸리\22년12월\모델고도화코드개발\스마트팜_혁신밸리_고도화_모델코드(전달)\고도화_GH_optimization_model_load_predict.py", line 325, in run
    if df is None or df.empty: raise Exception("데이터 전처리 및 병합 오류 발생")
Exception: 데이터 전처리 및 병합 오류 발생

2022-12-19 16:31:37,703 ERROR [GH_LOG] [고도화_GH_optimization_model_load_predict.py:339] - * 모듈 실행중 오류 발생 : 데이터 전처리 및 병합 오류 발생
2022-12-19 16:31:37,704 INFO [GH_LOG] [고도화_GH_optimization_model_load_predict.py:312] - [17384]GH Model 실행 : 임대형-03_딸기:
2022-12-19 16:31:38,448 ERROR [GH_LOG] [고도화_GH_optimization_model_load_predict.py:338] - Traceback (most recent call last):
  File "d:\theimz\조석준\NAVER_WORKS\스마트팜_혁신밸리\22년12월\모델고도화코드개발\스마트팜_혁신밸리_고도화_모델코드(전달)\고도화_GH_optimization_model_load_predict.py", line 325, in run
    if df is None or df.empty: raise Exception("데이터 전처리 및 병합 오류 발생")
Exception: 데이터 전처리 및 병합 오류 발생

2022-12-19 16:31:38,449 ERROR [GH_LOG] [고도화_GH_optimization_model_load_predict.py:339] - * 모듈 실행중 오류 발생 : 데이터 전처리 및 병합 오류 발생
2022-12-19 16:31:38,450 INFO [GH_LOG] [고도화_GH_optimization_model_load_predict.py:312] - [40916]GH Model 실행 : 임대형-04_딸기:
2022-12-19 16:31:38,861 ERROR [GH_LOG] [고도화_GH_optimization_model_load_predict.py:338] - Traceback (most recent call last):
  File "d:\theimz\조석준\NAVER_WORKS\스마트팜_혁신밸리\22년12월\모델고도화코드개발\스마트팜_혁신밸리_고도화_모델코드(전달)\고도화_GH_optimization_model_load_predict.py", line 333, in run
    GHModel.export_csv(self, predicted_value, prd_date)
  File "d:\theimz\조석준\NAVER_WORKS\스마트팜_혁신밸리\22년12월\모델고도화코드개발\스마트팜_혁신밸리_고도화_모델코드(전달)\고도화_GH_optimization_model_load_predict.py", line 280, in export_csv
    GH_env_monitor.loc[0] = [0,   self.fclty_nm, self.crop_nm, predicted_value[0], 0,   0,                  predicted_value[1],
IndexError: list index out of range

2022-12-19 16:31:38,863 ERROR [GH_LOG] [고도화_GH_optimization_model_load_predict.py:339] - * 모듈 실행중 오류 발생 : list index out of range
2022-12-19 16:31:38,892 ERROR [GH_LOG] [고도화_GH_optimization_model_load_predict.py:338] - Traceback (most recent call last):
  File "d:\theimz\조석준\NAVER_WORKS\스마트팜_혁신밸리\22년12월\모델고도화코드개발\스마트팜_혁신밸리_고도화_모델코드(전달)\고도화_GH_optimization_model_load_predict.py", line 333, in run
    GHModel.export_csv(self, predicted_value, prd_date)
  File "d:\theimz\조석준\NAVER_WORKS\스마트팜_혁신밸리\22년12월\모델고도화코드개발\스마트팜_혁신밸리_고도화_모델코드(전달)\고도화_GH_optimization_model_load_predict.py", line 280, in export_csv
    GH_env_monitor.loc[0] = [0,   self.fclty_nm, self.crop_nm, predicted_value[0], 0,   0,                  predicted_value[1],
IndexError: list index out of range

2022-12-19 16:31:38,894 ERROR [GH_LOG] [고도화_GH_optimization_model_load_predict.py:339] - * 모듈 실행중 오류 발생 : list index out of range
2022-12-19 16:31:40,926 ERROR [GH_LOG] [고도화_GH_optimization_model_load_predict.py:338] - Traceback (most recent call last):
  File "d:\theimz\조석준\NAVER_WORKS\스마트팜_혁신밸리\22년12월\모델고도화코드개발\스마트팜_혁신밸리_고도화_모델코드(전달)\고도화_GH_optimization_model_load_predict.py", line 325, in run
    if df is None or df.empty: raise Exception("데이터 전처리 및 병합 오류 발생")
Exception: 데이터 전처리 및 병합 오류 발생

2022-12-19 16:31:40,928 ERROR [GH_LOG] [고도화_GH_optimization_model_load_predict.py:339] - * 모듈 실행중 오류 발생 : 데이터 전처리 및 병합 오류 발생
2022-12-19 16:31:41,560 ERROR [GH_LOG] [고도화_GH_optimization_model_load_predict.py:338] - Traceback (most recent call last):
  File "d:\theimz\조석준\NAVER_WORKS\스마트팜_혁신밸리\22년12월\모델고도화코드개발\스마트팜_혁신밸리_고도화_모델코드(전달)\고도화_GH_optimization_model_load_predict.py", line 325, in run
    if df is None or df.empty: raise Exception("데이터 전처리 및 병합 오류 발생")
Exception: 데이터 전처리 및 병합 오류 발생

2022-12-19 16:31:41,561 ERROR [GH_LOG] [고도화_GH_optimization_model_load_predict.py:339] - * 모듈 실행중 오류 발생 : 데이터 전처리 및 병합 오류 발생
2022-12-19 16:31:42,201 INFO [GH_LOG] [고도화_GH_optimization_model_load_predict.py:379] - ** 모듈 실행 완료 > 총 실행시간 : 0:00:16.170312
2022-12-19 16:33:51,157 INFO [GH_LOG] [고도화_GH_optimization_model_load_predict.py:347] - GH optimization model : Start
2022-12-19 16:33:57,681 INFO [GH_LOG] [고도화_GH_optimization_model_load_predict.py:312] - [15672]GH Model 실행 : 경영형-01_딸기:
2022-12-19 16:33:57,714 INFO [GH_LOG] [고도화_GH_optimization_model_load_predict.py:312] - [19824]GH Model 실행 : 교육형-01_딸기:
2022-12-19 16:33:57,748 INFO [GH_LOG] [고도화_GH_optimization_model_load_predict.py:312] - [42884]GH Model 실행 : 임대형-01_딸기:
2022-12-19 16:33:57,753 INFO [GH_LOG] [고도화_GH_optimization_model_load_predict.py:312] - [34052]GH Model 실행 : 임대형-02_딸기:
2022-12-19 16:34:02,738 ERROR [GH_LOG] [고도화_GH_optimization_model_load_predict.py:338] - Traceback (most recent call last):
  File "d:\theimz\조석준\NAVER_WORKS\스마트팜_혁신밸리\22년12월\모델고도화코드개발\스마트팜_혁신밸리_고도화_모델코드(전달)\고도화_GH_optimization_model_load_predict.py", line 325, in run
    if df is None or df.empty: raise Exception("데이터 전처리 및 병합 오류 발생")
Exception: 데이터 전처리 및 병합 오류 발생

2022-12-19 16:34:02,739 ERROR [GH_LOG] [고도화_GH_optimization_model_load_predict.py:339] - * 모듈 실행중 오류 발생 : 데이터 전처리 및 병합 오류 발생
2022-12-19 16:34:02,739 INFO [GH_LOG] [고도화_GH_optimization_model_load_predict.py:312] - [34052]GH Model 실행 : 임대형-03_딸기:
2022-12-19 16:34:02,744 ERROR [GH_LOG] [고도화_GH_optimization_model_load_predict.py:338] - Traceback (most recent call last):
  File "d:\theimz\조석준\NAVER_WORKS\스마트팜_혁신밸리\22년12월\모델고도화코드개발\스마트팜_혁신밸리_고도화_모델코드(전달)\고도화_GH_optimization_model_load_predict.py", line 325, in run
    if df is None or df.empty: raise Exception("데이터 전처리 및 병합 오류 발생")
Exception: 데이터 전처리 및 병합 오류 발생

2022-12-19 16:34:02,745 ERROR [GH_LOG] [고도화_GH_optimization_model_load_predict.py:339] - * 모듈 실행중 오류 발생 : 데이터 전처리 및 병합 오류 발생
2022-12-19 16:34:02,746 INFO [GH_LOG] [고도화_GH_optimization_model_load_predict.py:312] - [42884]GH Model 실행 : 임대형-04_딸기:
2022-12-19 16:34:05,694 ERROR [GH_LOG] [고도화_GH_optimization_model_load_predict.py:265] - 예측하기 오류 발생
2022-12-19 16:34:05,694 ERROR [GH_LOG] [고도화_GH_optimization_model_load_predict.py:338] - Traceback (most recent call last):
  File "d:\theimz\조석준\NAVER_WORKS\스마트팜_혁신밸리\22년12월\모델고도화코드개발\스마트팜_혁신밸리_고도화_모델코드(전달)\고도화_GH_optimization_model_load_predict.py", line 330, in run
    predicted_value, prd_date = GHModel.pridict_model(self, df)
TypeError: cannot unpack non-iterable NoneType object

2022-12-19 16:34:05,695 ERROR [GH_LOG] [고도화_GH_optimization_model_load_predict.py:339] - * 모듈 실행중 오류 발생 : cannot unpack non-iterable NoneType object
2022-12-19 16:34:05,803 ERROR [GH_LOG] [고도화_GH_optimization_model_load_predict.py:265] - 예측하기 오류 발생
2022-12-19 16:34:05,803 ERROR [GH_LOG] [고도화_GH_optimization_model_load_predict.py:338] - Traceback (most recent call last):
  File "d:\theimz\조석준\NAVER_WORKS\스마트팜_혁신밸리\22년12월\모델고도화코드개발\스마트팜_혁신밸리_고도화_모델코드(전달)\고도화_GH_optimization_model_load_predict.py", line 330, in run
    predicted_value, prd_date = GHModel.pridict_model(self, df)
TypeError: cannot unpack non-iterable NoneType object

2022-12-19 16:34:05,804 ERROR [GH_LOG] [고도화_GH_optimization_model_load_predict.py:339] - * 모듈 실행중 오류 발생 : cannot unpack non-iterable NoneType object
2022-12-19 16:34:06,272 ERROR [GH_LOG] [고도화_GH_optimization_model_load_predict.py:338] - Traceback (most recent call last):
  File "d:\theimz\조석준\NAVER_WORKS\스마트팜_혁신밸리\22년12월\모델고도화코드개발\스마트팜_혁신밸리_고도화_모델코드(전달)\고도화_GH_optimization_model_load_predict.py", line 325, in run
    if df is None or df.empty: raise Exception("데이터 전처리 및 병합 오류 발생")
Exception: 데이터 전처리 및 병합 오류 발생

2022-12-19 16:34:06,273 ERROR [GH_LOG] [고도화_GH_optimization_model_load_predict.py:339] - * 모듈 실행중 오류 발생 : 데이터 전처리 및 병합 오류 발생
2022-12-19 16:34:06,307 ERROR [GH_LOG] [고도화_GH_optimization_model_load_predict.py:338] - Traceback (most recent call last):
  File "d:\theimz\조석준\NAVER_WORKS\스마트팜_혁신밸리\22년12월\모델고도화코드개발\스마트팜_혁신밸리_고도화_모델코드(전달)\고도화_GH_optimization_model_load_predict.py", line 325, in run
    if df is None or df.empty: raise Exception("데이터 전처리 및 병합 오류 발생")
Exception: 데이터 전처리 및 병합 오류 발생

2022-12-19 16:34:06,308 ERROR [GH_LOG] [고도화_GH_optimization_model_load_predict.py:339] - * 모듈 실행중 오류 발생 : 데이터 전처리 및 병합 오류 발생
2022-12-19 16:34:06,938 INFO [GH_LOG] [고도화_GH_optimization_model_load_predict.py:379] - ** 모듈 실행 완료 > 총 실행시간 : 0:00:15.780374
2022-12-19 16:37:15,956 INFO [GH_LOG] [고도화_GH_optimization_model_load_predict.py:348] - GH optimization model : Start
2022-12-19 16:37:22,325 INFO [GH_LOG] [고도화_GH_optimization_model_load_predict.py:313] - [16688]GH Model 실행 : 경영형-01_딸기:
2022-12-19 16:37:22,325 INFO [GH_LOG] [고도화_GH_optimization_model_load_predict.py:313] - [37620]GH Model 실행 : 교육형-01_딸기:
2022-12-19 16:37:22,400 INFO [GH_LOG] [고도화_GH_optimization_model_load_predict.py:313] - [13864]GH Model 실행 : 임대형-01_딸기:
2022-12-19 16:37:22,419 INFO [GH_LOG] [고도화_GH_optimization_model_load_predict.py:313] - [12120]GH Model 실행 : 임대형-02_딸기:
2022-12-19 16:37:27,443 ERROR [GH_LOG] [고도화_GH_optimization_model_load_predict.py:339] - Traceback (most recent call last):
  File "d:\theimz\조석준\NAVER_WORKS\스마트팜_혁신밸리\22년12월\모델고도화코드개발\스마트팜_혁신밸리_고도화_모델코드(전달)\고도화_GH_optimization_model_load_predict.py", line 326, in run
    if df is None or df.empty: raise Exception("데이터 전처리 및 병합 오류 발생")
Exception: 데이터 전처리 및 병합 오류 발생

2022-12-19 16:37:27,444 ERROR [GH_LOG] [고도화_GH_optimization_model_load_predict.py:340] - * 모듈 실행중 오류 발생 : 데이터 전처리 및 병합 오류 발생
2022-12-19 16:37:27,445 INFO [GH_LOG] [고도화_GH_optimization_model_load_predict.py:313] - [13864]GH Model 실행 : 임대형-03_딸기:
2022-12-19 16:37:27,470 ERROR [GH_LOG] [고도화_GH_optimization_model_load_predict.py:339] - Traceback (most recent call last):
  File "d:\theimz\조석준\NAVER_WORKS\스마트팜_혁신밸리\22년12월\모델고도화코드개발\스마트팜_혁신밸리_고도화_모델코드(전달)\고도화_GH_optimization_model_load_predict.py", line 326, in run
    if df is None or df.empty: raise Exception("데이터 전처리 및 병합 오류 발생")
Exception: 데이터 전처리 및 병합 오류 발생

2022-12-19 16:37:27,471 ERROR [GH_LOG] [고도화_GH_optimization_model_load_predict.py:340] - * 모듈 실행중 오류 발생 : 데이터 전처리 및 병합 오류 발생
2022-12-19 16:37:27,472 INFO [GH_LOG] [고도화_GH_optimization_model_load_predict.py:313] - [12120]GH Model 실행 : 임대형-04_딸기:
2022-12-19 16:37:31,048 ERROR [GH_LOG] [고도화_GH_optimization_model_load_predict.py:339] - Traceback (most recent call last):
  File "d:\theimz\조석준\NAVER_WORKS\스마트팜_혁신밸리\22년12월\모델고도화코드개발\스마트팜_혁신밸리_고도화_모델코드(전달)\고도화_GH_optimization_model_load_predict.py", line 326, in run
    if df is None or df.empty: raise Exception("데이터 전처리 및 병합 오류 발생")
Exception: 데이터 전처리 및 병합 오류 발생

2022-12-19 16:37:31,049 ERROR [GH_LOG] [고도화_GH_optimization_model_load_predict.py:340] - * 모듈 실행중 오류 발생 : 데이터 전처리 및 병합 오류 발생
2022-12-19 16:37:31,068 ERROR [GH_LOG] [고도화_GH_optimization_model_load_predict.py:339] - Traceback (most recent call last):
  File "d:\theimz\조석준\NAVER_WORKS\스마트팜_혁신밸리\22년12월\모델고도화코드개발\스마트팜_혁신밸리_고도화_모델코드(전달)\고도화_GH_optimization_model_load_predict.py", line 326, in run
    if df is None or df.empty: raise Exception("데이터 전처리 및 병합 오류 발생")
Exception: 데이터 전처리 및 병합 오류 발생

2022-12-19 16:37:31,069 ERROR [GH_LOG] [고도화_GH_optimization_model_load_predict.py:340] - * 모듈 실행중 오류 발생 : 데이터 전처리 및 병합 오류 발생
2022-12-19 16:37:32,274 INFO [GH_LOG] [고도화_GH_optimization_model_load_predict.py:289] - 결과 파일 저장 완료 - ./result/경영형-01_딸기_온실모니터링_10분뒤_예측.csv
2022-12-19 16:37:32,590 INFO [GH_LOG] [고도화_GH_optimization_model_load_predict.py:289] - 결과 파일 저장 완료 - ./result/교육형-01_딸기_온실모니터링_10분뒤_예측.csv
2022-12-19 16:37:32,628 ERROR [GH_LOG] [고도화_GH_optimization_model_load_predict.py:307] - Traceback (most recent call last):
  File "d:\theimz\조석준\NAVER_WORKS\스마트팜_혁신밸리\22년12월\모델고도화코드개발\스마트팜_혁신밸리_고도화_모델코드(전달)\고도화_GH_optimization_model_load_predict.py", line 303, in insert_into_db
    cursor.execute(query)
  File "C:\Anaconda3\envs\tf_env\lib\site-packages\pymysql\cursors.py", line 148, in execute
    result = self._query(query)
  File "C:\Anaconda3\envs\tf_env\lib\site-packages\pymysql\cursors.py", line 310, in _query
    conn.query(q)
  File "C:\Anaconda3\envs\tf_env\lib\site-packages\pymysql\connections.py", line 548, in query
    self._affected_rows = self._read_query_result(unbuffered=unbuffered)
  File "C:\Anaconda3\envs\tf_env\lib\site-packages\pymysql\connections.py", line 775, in _read_query_result
    result.read()
  File "C:\Anaconda3\envs\tf_env\lib\site-packages\pymysql\connections.py", line 1156, in read
    first_packet = self.connection._read_packet()
  File "C:\Anaconda3\envs\tf_env\lib\site-packages\pymysql\connections.py", line 725, in _read_packet
    packet.raise_for_error()
  File "C:\Anaconda3\envs\tf_env\lib\site-packages\pymysql\protocol.py", line 221, in raise_for_error
    err.raise_mysql_exception(self._data)
  File "C:\Anaconda3\envs\tf_env\lib\site-packages\pymysql\err.py", line 143, in raise_mysql_exception
    raise errorclass(errno, errval)
pymysql.err.OperationalError: (1136, "Column count doesn't match value count at row 1")

2022-12-19 16:37:32,630 ERROR [GH_LOG] [고도화_GH_optimization_model_load_predict.py:308] - 경영형-01_딸기 - 결과 DB 저장 오류 발생
2022-12-19 16:37:32,705 ERROR [GH_LOG] [고도화_GH_optimization_model_load_predict.py:307] - Traceback (most recent call last):
  File "d:\theimz\조석준\NAVER_WORKS\스마트팜_혁신밸리\22년12월\모델고도화코드개발\스마트팜_혁신밸리_고도화_모델코드(전달)\고도화_GH_optimization_model_load_predict.py", line 303, in insert_into_db
    cursor.execute(query)
  File "C:\Anaconda3\envs\tf_env\lib\site-packages\pymysql\cursors.py", line 148, in execute
    result = self._query(query)
  File "C:\Anaconda3\envs\tf_env\lib\site-packages\pymysql\cursors.py", line 310, in _query
    conn.query(q)
  File "C:\Anaconda3\envs\tf_env\lib\site-packages\pymysql\connections.py", line 548, in query
    self._affected_rows = self._read_query_result(unbuffered=unbuffered)
  File "C:\Anaconda3\envs\tf_env\lib\site-packages\pymysql\connections.py", line 775, in _read_query_result
    result.read()
  File "C:\Anaconda3\envs\tf_env\lib\site-packages\pymysql\connections.py", line 1156, in read
    first_packet = self.connection._read_packet()
  File "C:\Anaconda3\envs\tf_env\lib\site-packages\pymysql\connections.py", line 725, in _read_packet
    packet.raise_for_error()
  File "C:\Anaconda3\envs\tf_env\lib\site-packages\pymysql\protocol.py", line 221, in raise_for_error
    err.raise_mysql_exception(self._data)
  File "C:\Anaconda3\envs\tf_env\lib\site-packages\pymysql\err.py", line 143, in raise_mysql_exception
    raise errorclass(errno, errval)
pymysql.err.OperationalError: (1136, "Column count doesn't match value count at row 1")

2022-12-19 16:37:32,708 ERROR [GH_LOG] [고도화_GH_optimization_model_load_predict.py:308] - 교육형-01_딸기 - 결과 DB 저장 오류 발생
2022-12-19 16:37:33,377 INFO [GH_LOG] [고도화_GH_optimization_model_load_predict.py:380] - ** 모듈 실행 완료 > 총 실행시간 : 0:00:17.420011
2022-12-19 16:45:54,355 INFO [GH_LOG] [고도화_GH_optimization_model_load_predict.py:348] - GH optimization model : Start
2022-12-19 16:46:00,518 INFO [GH_LOG] [고도화_GH_optimization_model_load_predict.py:313] - [27368]GH Model 실행 : 경영형-01_딸기:
2022-12-19 16:46:00,525 INFO [GH_LOG] [고도화_GH_optimization_model_load_predict.py:313] - [42532]GH Model 실행 : 교육형-01_딸기:
2022-12-19 16:46:00,583 INFO [GH_LOG] [고도화_GH_optimization_model_load_predict.py:313] - [41908]GH Model 실행 : 임대형-01_딸기:
2022-12-19 16:46:00,586 INFO [GH_LOG] [고도화_GH_optimization_model_load_predict.py:313] - [39008]GH Model 실행 : 임대형-02_딸기:
2022-12-19 16:46:05,397 ERROR [GH_LOG] [고도화_GH_optimization_model_load_predict.py:339] - Traceback (most recent call last):
  File "d:\theimz\조석준\NAVER_WORKS\스마트팜_혁신밸리\22년12월\모델고도화코드개발\스마트팜_혁신밸리_고도화_모델코드(전달)\고도화_GH_optimization_model_load_predict.py", line 326, in run
    if df is None or df.empty: raise Exception("데이터 전처리 및 병합 오류 발생")
Exception: 데이터 전처리 및 병합 오류 발생

2022-12-19 16:46:05,399 ERROR [GH_LOG] [고도화_GH_optimization_model_load_predict.py:340] - * 모듈 실행중 오류 발생 : 데이터 전처리 및 병합 오류 발생
2022-12-19 16:46:05,399 INFO [GH_LOG] [고도화_GH_optimization_model_load_predict.py:313] - [41908]GH Model 실행 : 임대형-03_딸기:
2022-12-19 16:46:05,440 ERROR [GH_LOG] [고도화_GH_optimization_model_load_predict.py:339] - Traceback (most recent call last):
  File "d:\theimz\조석준\NAVER_WORKS\스마트팜_혁신밸리\22년12월\모델고도화코드개발\스마트팜_혁신밸리_고도화_모델코드(전달)\고도화_GH_optimization_model_load_predict.py", line 326, in run
    if df is None or df.empty: raise Exception("데이터 전처리 및 병합 오류 발생")
Exception: 데이터 전처리 및 병합 오류 발생

2022-12-19 16:46:05,441 ERROR [GH_LOG] [고도화_GH_optimization_model_load_predict.py:340] - * 모듈 실행중 오류 발생 : 데이터 전처리 및 병합 오류 발생
2022-12-19 16:46:05,442 INFO [GH_LOG] [고도화_GH_optimization_model_load_predict.py:313] - [39008]GH Model 실행 : 임대형-04_딸기:
2022-12-19 16:46:08,901 ERROR [GH_LOG] [고도화_GH_optimization_model_load_predict.py:339] - Traceback (most recent call last):
  File "d:\theimz\조석준\NAVER_WORKS\스마트팜_혁신밸리\22년12월\모델고도화코드개발\스마트팜_혁신밸리_고도화_모델코드(전달)\고도화_GH_optimization_model_load_predict.py", line 326, in run
    if df is None or df.empty: raise Exception("데이터 전처리 및 병합 오류 발생")
Exception: 데이터 전처리 및 병합 오류 발생

2022-12-19 16:46:08,902 ERROR [GH_LOG] [고도화_GH_optimization_model_load_predict.py:340] - * 모듈 실행중 오류 발생 : 데이터 전처리 및 병합 오류 발생
2022-12-19 16:46:09,021 ERROR [GH_LOG] [고도화_GH_optimization_model_load_predict.py:339] - Traceback (most recent call last):
  File "d:\theimz\조석준\NAVER_WORKS\스마트팜_혁신밸리\22년12월\모델고도화코드개발\스마트팜_혁신밸리_고도화_모델코드(전달)\고도화_GH_optimization_model_load_predict.py", line 326, in run
    if df is None or df.empty: raise Exception("데이터 전처리 및 병합 오류 발생")
Exception: 데이터 전처리 및 병합 오류 발생

2022-12-19 16:46:09,022 ERROR [GH_LOG] [고도화_GH_optimization_model_load_predict.py:340] - * 모듈 실행중 오류 발생 : 데이터 전처리 및 병합 오류 발생
2022-12-19 16:46:10,258 ERROR [GH_LOG] [고도화_GH_optimization_model_load_predict.py:339] - Traceback (most recent call last):
  File "d:\theimz\조석준\NAVER_WORKS\스마트팜_혁신밸리\22년12월\모델고도화코드개발\스마트팜_혁신밸리_고도화_모델코드(전달)\고도화_GH_optimization_model_load_predict.py", line 334, in run
    GHModel.export_csv(self, predicted_value, prd_date)
  File "d:\theimz\조석준\NAVER_WORKS\스마트팜_혁신밸리\22년12월\모델고도화코드개발\스마트팜_혁신밸리_고도화_모델코드(전달)\고도화_GH_optimization_model_load_predict.py", line 281, in export_csv
    GH_env_monitor.loc[0] = [0,   self.fclty_nm, self.crop_nm, predicted_value[0], 0,   0,                  predicted_value[1],
IndexError: list index out of range

2022-12-19 16:46:10,260 ERROR [GH_LOG] [고도화_GH_optimization_model_load_predict.py:340] - * 모듈 실행중 오류 발생 : list index out of range
2022-12-19 16:46:10,562 ERROR [GH_LOG] [고도화_GH_optimization_model_load_predict.py:339] - Traceback (most recent call last):
  File "d:\theimz\조석준\NAVER_WORKS\스마트팜_혁신밸리\22년12월\모델고도화코드개발\스마트팜_혁신밸리_고도화_모델코드(전달)\고도화_GH_optimization_model_load_predict.py", line 334, in run
    GHModel.export_csv(self, predicted_value, prd_date)
  File "d:\theimz\조석준\NAVER_WORKS\스마트팜_혁신밸리\22년12월\모델고도화코드개발\스마트팜_혁신밸리_고도화_모델코드(전달)\고도화_GH_optimization_model_load_predict.py", line 281, in export_csv
    GH_env_monitor.loc[0] = [0,   self.fclty_nm, self.crop_nm, predicted_value[0], 0,   0,                  predicted_value[1],
IndexError: list index out of range

2022-12-19 16:46:10,563 ERROR [GH_LOG] [고도화_GH_optimization_model_load_predict.py:340] - * 모듈 실행중 오류 발생 : list index out of range
2022-12-19 16:46:11,240 INFO [GH_LOG] [고도화_GH_optimization_model_load_predict.py:380] - ** 모듈 실행 완료 > 총 실행시간 : 0:00:16.885001
2022-12-19 16:47:07,542 INFO [GH_LOG] [고도화_GH_optimization_model_load_predict.py:348] - GH optimization model : Start
2022-12-19 16:47:14,097 INFO [GH_LOG] [고도화_GH_optimization_model_load_predict.py:313] - [26292]GH Model 실행 : 경영형-01_딸기:
2022-12-19 16:47:14,117 INFO [GH_LOG] [고도화_GH_optimization_model_load_predict.py:313] - [11304]GH Model 실행 : 교육형-01_딸기:
2022-12-19 16:47:14,152 INFO [GH_LOG] [고도화_GH_optimization_model_load_predict.py:313] - [17960]GH Model 실행 : 임대형-01_딸기:
2022-12-19 16:47:14,170 INFO [GH_LOG] [고도화_GH_optimization_model_load_predict.py:313] - [9300]GH Model 실행 : 임대형-02_딸기:
2022-12-19 16:47:19,441 ERROR [GH_LOG] [고도화_GH_optimization_model_load_predict.py:339] - Traceback (most recent call last):
  File "d:\theimz\조석준\NAVER_WORKS\스마트팜_혁신밸리\22년12월\모델고도화코드개발\스마트팜_혁신밸리_고도화_모델코드(전달)\고도화_GH_optimization_model_load_predict.py", line 326, in run
    if df is None or df.empty: raise Exception("데이터 전처리 및 병합 오류 발생")
Exception: 데이터 전처리 및 병합 오류 발생

2022-12-19 16:47:19,442 ERROR [GH_LOG] [고도화_GH_optimization_model_load_predict.py:340] - * 모듈 실행중 오류 발생 : 데이터 전처리 및 병합 오류 발생
2022-12-19 16:47:19,443 INFO [GH_LOG] [고도화_GH_optimization_model_load_predict.py:313] - [9300]GH Model 실행 : 임대형-03_딸기:
2022-12-19 16:47:19,754 ERROR [GH_LOG] [고도화_GH_optimization_model_load_predict.py:339] - Traceback (most recent call last):
  File "d:\theimz\조석준\NAVER_WORKS\스마트팜_혁신밸리\22년12월\모델고도화코드개발\스마트팜_혁신밸리_고도화_모델코드(전달)\고도화_GH_optimization_model_load_predict.py", line 326, in run
    if df is None or df.empty: raise Exception("데이터 전처리 및 병합 오류 발생")
Exception: 데이터 전처리 및 병합 오류 발생

2022-12-19 16:47:19,755 ERROR [GH_LOG] [고도화_GH_optimization_model_load_predict.py:340] - * 모듈 실행중 오류 발생 : 데이터 전처리 및 병합 오류 발생
2022-12-19 16:47:19,756 INFO [GH_LOG] [고도화_GH_optimization_model_load_predict.py:313] - [17960]GH Model 실행 : 임대형-04_딸기:
2022-12-19 16:47:23,278 ERROR [GH_LOG] [고도화_GH_optimization_model_load_predict.py:339] - Traceback (most recent call last):
  File "d:\theimz\조석준\NAVER_WORKS\스마트팜_혁신밸리\22년12월\모델고도화코드개발\스마트팜_혁신밸리_고도화_모델코드(전달)\고도화_GH_optimization_model_load_predict.py", line 326, in run
    if df is None or df.empty: raise Exception("데이터 전처리 및 병합 오류 발생")
Exception: 데이터 전처리 및 병합 오류 발생

2022-12-19 16:47:23,279 ERROR [GH_LOG] [고도화_GH_optimization_model_load_predict.py:340] - * 모듈 실행중 오류 발생 : 데이터 전처리 및 병합 오류 발생
2022-12-19 16:47:23,289 ERROR [GH_LOG] [고도화_GH_optimization_model_load_predict.py:339] - Traceback (most recent call last):
  File "d:\theimz\조석준\NAVER_WORKS\스마트팜_혁신밸리\22년12월\모델고도화코드개발\스마트팜_혁신밸리_고도화_모델코드(전달)\고도화_GH_optimization_model_load_predict.py", line 326, in run
    if df is None or df.empty: raise Exception("데이터 전처리 및 병합 오류 발생")
Exception: 데이터 전처리 및 병합 오류 발생

2022-12-19 16:47:23,290 ERROR [GH_LOG] [고도화_GH_optimization_model_load_predict.py:340] - * 모듈 실행중 오류 발생 : 데이터 전처리 및 병합 오류 발생
2022-12-19 16:47:24,333 ERROR [GH_LOG] [고도화_GH_optimization_model_load_predict.py:339] - Traceback (most recent call last):
  File "d:\theimz\조석준\NAVER_WORKS\스마트팜_혁신밸리\22년12월\모델고도화코드개발\스마트팜_혁신밸리_고도화_모델코드(전달)\고도화_GH_optimization_model_load_predict.py", line 334, in run
    GHModel.export_csv(self, predicted_value, prd_date)
  File "d:\theimz\조석준\NAVER_WORKS\스마트팜_혁신밸리\22년12월\모델고도화코드개발\스마트팜_혁신밸리_고도화_모델코드(전달)\고도화_GH_optimization_model_load_predict.py", line 281, in export_csv
    GH_env_monitor.loc[0] = [0,   self.fclty_nm, self.crop_nm, predicted_value[0], 0,   0,                  predicted_value[1],
IndexError: list index out of range

2022-12-19 16:47:24,335 ERROR [GH_LOG] [고도화_GH_optimization_model_load_predict.py:340] - * 모듈 실행중 오류 발생 : list index out of range
2022-12-19 16:47:24,557 ERROR [GH_LOG] [고도화_GH_optimization_model_load_predict.py:339] - Traceback (most recent call last):
  File "d:\theimz\조석준\NAVER_WORKS\스마트팜_혁신밸리\22년12월\모델고도화코드개발\스마트팜_혁신밸리_고도화_모델코드(전달)\고도화_GH_optimization_model_load_predict.py", line 334, in run
    GHModel.export_csv(self, predicted_value, prd_date)
  File "d:\theimz\조석준\NAVER_WORKS\스마트팜_혁신밸리\22년12월\모델고도화코드개발\스마트팜_혁신밸리_고도화_모델코드(전달)\고도화_GH_optimization_model_load_predict.py", line 281, in export_csv
    GH_env_monitor.loc[0] = [0,   self.fclty_nm, self.crop_nm, predicted_value[0], 0,   0,                  predicted_value[1],
IndexError: list index out of range

2022-12-19 16:47:24,558 ERROR [GH_LOG] [고도화_GH_optimization_model_load_predict.py:340] - * 모듈 실행중 오류 발생 : list index out of range
2022-12-19 16:47:25,243 INFO [GH_LOG] [고도화_GH_optimization_model_load_predict.py:380] - ** 모듈 실행 완료 > 총 실행시간 : 0:00:17.701116
2022-12-19 16:53:54,960 INFO [GH_LOG] [고도화_GH_optimization_model_load_predict.py:348] - GH optimization model : Start
2022-12-19 16:54:01,365 INFO [GH_LOG] [고도화_GH_optimization_model_load_predict.py:313] - [25572]GH Model 실행 : 경영형-01_딸기:
2022-12-19 16:54:01,382 INFO [GH_LOG] [고도화_GH_optimization_model_load_predict.py:313] - [30120]GH Model 실행 : 교육형-01_딸기:
2022-12-19 16:54:01,534 INFO [GH_LOG] [고도화_GH_optimization_model_load_predict.py:313] - [34172]GH Model 실행 : 임대형-01_딸기:
2022-12-19 16:54:01,541 INFO [GH_LOG] [고도화_GH_optimization_model_load_predict.py:313] - [12008]GH Model 실행 : 임대형-02_딸기:
2022-12-19 16:54:06,683 ERROR [GH_LOG] [고도화_GH_optimization_model_load_predict.py:339] - Traceback (most recent call last):
  File "d:\theimz\조석준\NAVER_WORKS\스마트팜_혁신밸리\22년12월\모델고도화코드개발\스마트팜_혁신밸리_고도화_모델코드(전달)\고도화_GH_optimization_model_load_predict.py", line 326, in run
    if df is None or df.empty: raise Exception("데이터 전처리 및 병합 오류 발생")
Exception: 데이터 전처리 및 병합 오류 발생

2022-12-19 16:54:06,684 ERROR [GH_LOG] [고도화_GH_optimization_model_load_predict.py:340] - * 모듈 실행중 오류 발생 : 데이터 전처리 및 병합 오류 발생
2022-12-19 16:54:06,685 INFO [GH_LOG] [고도화_GH_optimization_model_load_predict.py:313] - [34172]GH Model 실행 : 임대형-03_딸기:
2022-12-19 16:54:06,723 ERROR [GH_LOG] [고도화_GH_optimization_model_load_predict.py:339] - Traceback (most recent call last):
  File "d:\theimz\조석준\NAVER_WORKS\스마트팜_혁신밸리\22년12월\모델고도화코드개발\스마트팜_혁신밸리_고도화_모델코드(전달)\고도화_GH_optimization_model_load_predict.py", line 326, in run
    if df is None or df.empty: raise Exception("데이터 전처리 및 병합 오류 발생")
Exception: 데이터 전처리 및 병합 오류 발생

2022-12-19 16:54:06,725 ERROR [GH_LOG] [고도화_GH_optimization_model_load_predict.py:340] - * 모듈 실행중 오류 발생 : 데이터 전처리 및 병합 오류 발생
2022-12-19 16:54:06,725 INFO [GH_LOG] [고도화_GH_optimization_model_load_predict.py:313] - [12008]GH Model 실행 : 임대형-04_딸기:
2022-12-19 16:54:10,286 ERROR [GH_LOG] [고도화_GH_optimization_model_load_predict.py:339] - Traceback (most recent call last):
  File "d:\theimz\조석준\NAVER_WORKS\스마트팜_혁신밸리\22년12월\모델고도화코드개발\스마트팜_혁신밸리_고도화_모델코드(전달)\고도화_GH_optimization_model_load_predict.py", line 326, in run
    if df is None or df.empty: raise Exception("데이터 전처리 및 병합 오류 발생")
Exception: 데이터 전처리 및 병합 오류 발생

2022-12-19 16:54:10,287 ERROR [GH_LOG] [고도화_GH_optimization_model_load_predict.py:340] - * 모듈 실행중 오류 발생 : 데이터 전처리 및 병합 오류 발생
2022-12-19 16:54:10,325 ERROR [GH_LOG] [고도화_GH_optimization_model_load_predict.py:339] - Traceback (most recent call last):
  File "d:\theimz\조석준\NAVER_WORKS\스마트팜_혁신밸리\22년12월\모델고도화코드개발\스마트팜_혁신밸리_고도화_모델코드(전달)\고도화_GH_optimization_model_load_predict.py", line 326, in run
    if df is None or df.empty: raise Exception("데이터 전처리 및 병합 오류 발생")
Exception: 데이터 전처리 및 병합 오류 발생

2022-12-19 16:54:10,326 ERROR [GH_LOG] [고도화_GH_optimization_model_load_predict.py:340] - * 모듈 실행중 오류 발생 : 데이터 전처리 및 병합 오류 발생
2022-12-19 16:54:11,727 INFO [GH_LOG] [고도화_GH_optimization_model_load_predict.py:289] - 결과 파일 저장 완료 - ./result/경영형-01_딸기_온실모니터링_10분뒤_예측.csv
2022-12-19 16:54:12,031 INFO [GH_LOG] [고도화_GH_optimization_model_load_predict.py:289] - 결과 파일 저장 완료 - ./result/교육형-01_딸기_온실모니터링_10분뒤_예측.csv
2022-12-19 16:54:12,167 ERROR [GH_LOG] [고도화_GH_optimization_model_load_predict.py:307] - Traceback (most recent call last):
  File "d:\theimz\조석준\NAVER_WORKS\스마트팜_혁신밸리\22년12월\모델고도화코드개발\스마트팜_혁신밸리_고도화_모델코드(전달)\고도화_GH_optimization_model_load_predict.py", line 303, in insert_into_db
    cursor.execute(query)
  File "C:\Anaconda3\envs\tf_env\lib\site-packages\pymysql\cursors.py", line 148, in execute
    result = self._query(query)
  File "C:\Anaconda3\envs\tf_env\lib\site-packages\pymysql\cursors.py", line 310, in _query
    conn.query(q)
  File "C:\Anaconda3\envs\tf_env\lib\site-packages\pymysql\connections.py", line 548, in query
    self._affected_rows = self._read_query_result(unbuffered=unbuffered)
  File "C:\Anaconda3\envs\tf_env\lib\site-packages\pymysql\connections.py", line 775, in _read_query_result
    result.read()
  File "C:\Anaconda3\envs\tf_env\lib\site-packages\pymysql\connections.py", line 1156, in read
    first_packet = self.connection._read_packet()
  File "C:\Anaconda3\envs\tf_env\lib\site-packages\pymysql\connections.py", line 725, in _read_packet
    packet.raise_for_error()
  File "C:\Anaconda3\envs\tf_env\lib\site-packages\pymysql\protocol.py", line 221, in raise_for_error
    err.raise_mysql_exception(self._data)
  File "C:\Anaconda3\envs\tf_env\lib\site-packages\pymysql\err.py", line 143, in raise_mysql_exception
    raise errorclass(errno, errval)
pymysql.err.OperationalError: (1136, "Column count doesn't match value count at row 1")

2022-12-19 16:54:12,170 ERROR [GH_LOG] [고도화_GH_optimization_model_load_predict.py:308] - 교육형-01_딸기 - 결과 DB 저장 오류 발생
2022-12-19 16:54:12,828 ERROR [GH_LOG] [고도화_GH_optimization_model_load_predict.py:307] - Traceback (most recent call last):
  File "d:\theimz\조석준\NAVER_WORKS\스마트팜_혁신밸리\22년12월\모델고도화코드개발\스마트팜_혁신밸리_고도화_모델코드(전달)\고도화_GH_optimization_model_load_predict.py", line 303, in insert_into_db
    cursor.execute(query)
  File "C:\Anaconda3\envs\tf_env\lib\site-packages\pymysql\cursors.py", line 148, in execute
    result = self._query(query)
  File "C:\Anaconda3\envs\tf_env\lib\site-packages\pymysql\cursors.py", line 310, in _query
    conn.query(q)
  File "C:\Anaconda3\envs\tf_env\lib\site-packages\pymysql\connections.py", line 548, in query
    self._affected_rows = self._read_query_result(unbuffered=unbuffered)
  File "C:\Anaconda3\envs\tf_env\lib\site-packages\pymysql\connections.py", line 775, in _read_query_result
    result.read()
  File "C:\Anaconda3\envs\tf_env\lib\site-packages\pymysql\connections.py", line 1156, in read
    first_packet = self.connection._read_packet()
  File "C:\Anaconda3\envs\tf_env\lib\site-packages\pymysql\connections.py", line 725, in _read_packet
    packet.raise_for_error()
  File "C:\Anaconda3\envs\tf_env\lib\site-packages\pymysql\protocol.py", line 221, in raise_for_error
    err.raise_mysql_exception(self._data)
  File "C:\Anaconda3\envs\tf_env\lib\site-packages\pymysql\err.py", line 143, in raise_mysql_exception
    raise errorclass(errno, errval)
pymysql.err.OperationalError: (1136, "Column count doesn't match value count at row 1")

2022-12-19 16:54:12,830 ERROR [GH_LOG] [고도화_GH_optimization_model_load_predict.py:308] - 경영형-01_딸기 - 결과 DB 저장 오류 발생
2022-12-19 16:54:13,502 INFO [GH_LOG] [고도화_GH_optimization_model_load_predict.py:380] - ** 모듈 실행 완료 > 총 실행시간 : 0:00:18.541939
2022-12-19 16:56:43,601 INFO [GH_LOG] [고도화_GH_optimization_model_load_predict.py:348] - GH optimization model : Start
2022-12-19 16:56:49,800 INFO [GH_LOG] [고도화_GH_optimization_model_load_predict.py:313] - [6480]GH Model 실행 : 경영형-01_딸기:
2022-12-19 16:56:49,904 INFO [GH_LOG] [고도화_GH_optimization_model_load_predict.py:313] - [17584]GH Model 실행 : 교육형-01_딸기:
2022-12-19 16:56:49,937 INFO [GH_LOG] [고도화_GH_optimization_model_load_predict.py:313] - [9708]GH Model 실행 : 임대형-01_딸기:
2022-12-19 16:56:49,937 INFO [GH_LOG] [고도화_GH_optimization_model_load_predict.py:313] - [37784]GH Model 실행 : 임대형-02_딸기:
2022-12-19 16:56:54,711 ERROR [GH_LOG] [고도화_GH_optimization_model_load_predict.py:339] - Traceback (most recent call last):
  File "d:\theimz\조석준\NAVER_WORKS\스마트팜_혁신밸리\22년12월\모델고도화코드개발\스마트팜_혁신밸리_고도화_모델코드(전달)\고도화_GH_optimization_model_load_predict.py", line 326, in run
    if df is None or df.empty: raise Exception("데이터 전처리 및 병합 오류 발생")
Exception: 데이터 전처리 및 병합 오류 발생

2022-12-19 16:56:54,712 ERROR [GH_LOG] [고도화_GH_optimization_model_load_predict.py:340] - * 모듈 실행중 오류 발생 : 데이터 전처리 및 병합 오류 발생
2022-12-19 16:56:54,713 INFO [GH_LOG] [고도화_GH_optimization_model_load_predict.py:313] - [37784]GH Model 실행 : 임대형-03_딸기:
2022-12-19 16:56:54,770 ERROR [GH_LOG] [고도화_GH_optimization_model_load_predict.py:339] - Traceback (most recent call last):
  File "d:\theimz\조석준\NAVER_WORKS\스마트팜_혁신밸리\22년12월\모델고도화코드개발\스마트팜_혁신밸리_고도화_모델코드(전달)\고도화_GH_optimization_model_load_predict.py", line 326, in run
    if df is None or df.empty: raise Exception("데이터 전처리 및 병합 오류 발생")
Exception: 데이터 전처리 및 병합 오류 발생

2022-12-19 16:56:54,771 ERROR [GH_LOG] [고도화_GH_optimization_model_load_predict.py:340] - * 모듈 실행중 오류 발생 : 데이터 전처리 및 병합 오류 발생
2022-12-19 16:56:54,771 INFO [GH_LOG] [고도화_GH_optimization_model_load_predict.py:313] - [9708]GH Model 실행 : 임대형-04_딸기:
2022-12-19 16:56:58,184 ERROR [GH_LOG] [고도화_GH_optimization_model_load_predict.py:339] - Traceback (most recent call last):
  File "d:\theimz\조석준\NAVER_WORKS\스마트팜_혁신밸리\22년12월\모델고도화코드개발\스마트팜_혁신밸리_고도화_모델코드(전달)\고도화_GH_optimization_model_load_predict.py", line 326, in run
    if df is None or df.empty: raise Exception("데이터 전처리 및 병합 오류 발생")
Exception: 데이터 전처리 및 병합 오류 발생

2022-12-19 16:56:58,185 ERROR [GH_LOG] [고도화_GH_optimization_model_load_predict.py:340] - * 모듈 실행중 오류 발생 : 데이터 전처리 및 병합 오류 발생
2022-12-19 16:56:58,241 ERROR [GH_LOG] [고도화_GH_optimization_model_load_predict.py:339] - Traceback (most recent call last):
  File "d:\theimz\조석준\NAVER_WORKS\스마트팜_혁신밸리\22년12월\모델고도화코드개발\스마트팜_혁신밸리_고도화_모델코드(전달)\고도화_GH_optimization_model_load_predict.py", line 326, in run
    if df is None or df.empty: raise Exception("데이터 전처리 및 병합 오류 발생")
Exception: 데이터 전처리 및 병합 오류 발생

2022-12-19 16:56:58,242 ERROR [GH_LOG] [고도화_GH_optimization_model_load_predict.py:340] - * 모듈 실행중 오류 발생 : 데이터 전처리 및 병합 오류 발생
2022-12-19 16:56:59,540 INFO [GH_LOG] [고도화_GH_optimization_model_load_predict.py:289] - 결과 파일 저장 완료 - ./result/경영형-01_딸기_온실모니터링_10분뒤_예측.csv
2022-12-19 16:56:59,644 INFO [GH_LOG] [고도화_GH_optimization_model_load_predict.py:305] - 경영형-01_딸기 - 결과 DB 저장 완료
2022-12-19 16:57:00,230 INFO [GH_LOG] [고도화_GH_optimization_model_load_predict.py:289] - 결과 파일 저장 완료 - ./result/교육형-01_딸기_온실모니터링_10분뒤_예측.csv
2022-12-19 16:57:00,322 INFO [GH_LOG] [고도화_GH_optimization_model_load_predict.py:305] - 교육형-01_딸기 - 결과 DB 저장 완료
2022-12-19 16:57:00,997 INFO [GH_LOG] [고도화_GH_optimization_model_load_predict.py:380] - ** 모듈 실행 완료 > 총 실행시간 : 0:00:17.393482
